Workbook

Sheet 1223有医院代码
A1: CSO编号 | B1: 医生姓名 | C1: 性别 | D1: 医院名称 | E1: 医院ID | F1: 标准科室 | G1: 专业职称 | H1: 手机号 | I1: 所属员工邮箱
A2: CSO00000001 | B2: 于占彪 | C2: 男 | D2: 河北大学附属医院 | E2: =VLOOKUP($D2,[1]医生名单!$M:$N,2,0) -> H1306009 | F2: ICU | G2: 主任医师 | H2: 15188655821 | I2: xiangyu.gao@everestmedicines.com
A3: CSO00000002 | B3: 赵松颖 | C3: 女 | D3: 河北大学附属医院 | E3: =VLOOKUP($D3,[1]医生名单!$M:$N,2,0) -> H1306009 | F3: 血液科 | G3: 主任医师 | H3: 15031273319 | I3: xiangyu.gao@everestmedicines.com
A4: CSO00000003 | B4: 高峰 | C4: 男 | D4: 华北理工大学附属医院 | E4: =VLOOKUP($D4,[1]医生名单!$M:$N,2,0) -> H1302010 | F4: 血液科 | G4: 主任医师 | H4: 15383057877 | I4: xiangyu.gao@everestmedicines.com
A5: CSO00000004 | B5: 张海霞 | C5: 女 | D5: 华北理工大学附属医院 | E5: =VLOOKUP($D5,[1]医生名单!$M:$N,2,0) -> H1302010 | F5: 血液科 | G5: 主任医师 | H5: 15383055878 | I5: xiangyu.gao@everestmedicines.com
A6: CSO00000005 | B6: 郑丽坤 | C6: 女 | D6: 华北理工大学附属医院 | E6: =VLOOKUP($D6,[1]医生名单!$M:$N,2,0) -> H1302010 | F6: 血液科 | G6: 主任医师 | H6: 15373569166 | I6: xiangyu.gao@everestmedicines.com
A7: CSO00000006 | B7: 杨美荣 | C7: 女 | D7: 华北理工大学附属医院 | E7: =VLOOKUP($D7,[1]医生名单!$M:$N,2,0) -> H1302010 | F7: 血液科 | G7: 主任医师 | H7: 13832964045 | I7: xiangyu.gao@everestmedicines.com
A8: CSO00000007 | B8: 冯术青 | C8: 女 | D8: 华北理工大学附属医院 | E8: =VLOOKUP($D8,[1]医生名单!$M:$N,2,0) -> H1302010 | F8: 血液科 | G8: 主任医师 | H8: 13832833342 | I8: xiangyu.gao@everestmedicines.com
A9: CSO00000008 | B9: 白静 | C9: 女 | D9: 华北理工大学附属医院 | E9: =VLOOKUP($D9,[1]医生名单!$M:$N,2,0) -> H1302010 | F9: ICU | G9: 主任医师 | H9: 18032538681 | I9: xiangyu.gao@everestmedicines.com
A10: CSO00000009 | B10: 王宝华 | C10: 男 | D10: 华北理工大学附属医院 | E10: =VLOOKUP($D10,[1]医生名单!$M:$N,2,0) -> H1302010 | F10: ICU | G10: 副主任医师 | H10: 13383059991 | I10: xiangyu.gao@everestmedicines.com
A11: CSO00000010 | B11: 程爱斌 | C11: 男 | D11: 华北理工大学附属医院 | E11: =VLOOKUP($D11,[1]医生名单!$M:$N,2,0) -> H1302010 | F11: ICU | G11: 主任医师 | H11: 15383055978 | I11: xiangyu.gao@everestmedicines.com
A12: CSO00000011 | B12: 王建军 | C12: 男 | D12: 华北理工大学附属医院 | E12: =VLOOKUP($D12,[1]医生名单!$M:$N,2,0) -> H1302010 | F12: ICU | G12: 副主任医师 | H12: 13832585692 | I12: xiangyu.gao@everestmedicines.com
A13: CSO00000012 | B13: 王瑞刚 | C13: 男 | D13: 华北理工大学附属医院 | E13: =VLOOKUP($D13,[1]医生名单!$M:$N,2,0) -> H1302010 | F13: ICU | G13: 主任医师 | H13: 18632511199 | I13: xiangyu.gao@everestmedicines.com
... A24: CSO00000023 | B24: 赵坤宵 | C24: 女 | D24: 河北医科大学第一医院 | E24: =VLOOKUP($D24,[1]医生名单!$M:$N,2,0) -> H1301040 | F24: 肾内科 | G24: 主任医师 | H24: 18032695022 | I24: xiangyu.gao@everestmedicines.com
A25: CSO00000024 | B25: 赵帅 | C25: 女 | D25: 河北医科大学第一医院 | E25: =VLOOKUP($D25,[1]医生名单!$M:$N,2,0) -> H1301040 | F25: 医学检验科 | G25: 主任技师 | H25: 135 6005 5928 | I25: xiangyu.gao@everestmedicines.com
A26: CSO00000025 | B26: 王嘉 | C26: 女 | D26: 河北医科大学第一医院 | E26: =VLOOKUP($D26,[1]医生名单!$M:$N,2,0) -> H1301040 | F26: 感染科 | G26: 主任医师 | H26: 18633889952 | I26: xiangyu.gao@everestmedicines.com
A27: CSO00000026 | B27: 田佳 | C27: 女 | D27: 河北医科大学第一医院 | E27: =VLOOKUP($D27,[1]医生名单!$M:$N,2,0) -> H1301040 | F27: 综合ICU | G27: 主任医师 | H27: 18633888269 | I27: xiangyu.gao@everestmedicines.com
A28: CSO00000027 | B28: 李杰 | C28: 男 | D28: 河北省人民医院 | E28: =VLOOKUP($D28,[1]医生名单!$M:$N,2,0) -> H1301001 | F28: 血液科 | G28: 主任医师 | H28: 13831198951 | I28: xiangyu.gao@everestmedicines.com
A29: CSO00000028 | B29: 申丽旻 | C29: 女 | D29: 河北省人民医院 | E29: =VLOOKUP($D29,[1]医生名单!$M:$N,2,0) -> H1301001 | F29: 综合ICU | G29: 主任医师 | H29: 13230116311 | I29: xiangyu.gao@everestmedicines.com
A30: CSO00000029 | B30: 杜全胜 | C30: 男 | D30: 河北省人民医院 | E30: =VLOOKUP($D30,[1]医生名单!$M:$N,2,0) -> H1301001 | F30: 急诊科 | G30: 副主任医师 | H30: 13230163769 | I30: xiangyu.gao@everestmedicines.com
A31: CSO00000030 | B31: 任珊 | C31: 女 | D31: 河北省人民医院 | E31: =VLOOKUP($D31,[1]医生名单!$M:$N,2,0) -> H1301001 | F31: 综合ICU | G31: 副主任医师 | H31: 15832141860 | I31: xiangyu.gao@everestmedicines.com
A32: CSO00000031 | B32: 闫莉 | C32: 女 | D32: 河北省人民医院 | E32: =VLOOKUP($D32,[1]医生名单!$M:$N,2,0) -> H1301001 | F32: 呼吸ICU | G32: 主任医师 | H32: 18203207882 | I32: xiangyu.gao@everestmedicines.com
A33: CSO00000032 | B33: 刘洪英 | C33: 女 | D33: 河北省人民医院 | E33: =VLOOKUP($D33,[1]医生名单!$M:$N,2,0) -> H1301001 | F33: 感染科 | G33: 主任医师 | H33: 18831115603 | I33: xiangyu.gao@everestmedicines.com
A34: CSO00000033 | B34: 宫小薇 | C34: 女 | D34: 河北医科大学第二医院 | E34: =VLOOKUP($D34,[1]医生名单!$M:$N,2,0) -> H1301002 | F34: 呼吸ICU | G34: 副主任医师 | H34: 15833119392 | I34: xiangyu.gao@everestmedicines.com
A35: CSO00000034 | B35: 于婧 | C35: 女 | D35: 河北医科大学第二医院 | E35: =VLOOKUP($D35,[1]医生名单!$M:$N,2,0) -> H1301002 | F35: 呼吸ICU | G35: 副主任医师 | H35: 15833952017 | I35: xiangyu.gao@everestmedicines.com
A36: CSO00000035 | B36: 潘文森 | C36: 男 | D36: 河北医科大学第二医院 | E36: =VLOOKUP($D36,[1]医生名单!$M:$N,2,0) -> H1301002 | F36: 呼吸ICU | G36: 主任医师 | H36: 18233106557 | I36: xiangyu.gao@everestmedicines.com
A37: CSO00000036 | B37: 高恒波 | C37: 男 | D37: 河北医科大学第二医院 | E37: =VLOOKUP($D37,[1]医生名单!$M:$N,2,0) -> H1301002 | F37: 急诊ICU | G37: 主任医师 | H37: 18233106588 | I37: xiangyu.gao@everestmedicines.com
... A112: CSO00000111 | B112: 张朝辉 | C112: 男 | D112: 宜昌市中心人民医院 | E112: =VLOOKUP($D112,[1]医生名单!$M:$N,2,0) -> H4205001 | F112: ICU | G112: 主任医师 | H112: 15071737290 | I112: jin.zhang@everestmedicines.com
A113: CSO00000112 | B113: 龚勋 | C113: 男 | D113: 宜昌市中心人民医院 | E113: =VLOOKUP($D113,[1]医生名单!$M:$N,2,0) -> H4205001 | F113: ICU | G113: 副主任医师 | H113: 158 7254 9520 | I113: jin.zhang@everestmedicines.com
A114: CSO00000113 | B114: 钟建华 | C114: 女 | D114: 宜昌市中心人民医院 | E114: =VLOOKUP($D114,[1]医生名单!$M:$N,2,0) -> H4205001 | F114: ICU | G114: 副主任医师 | H114: 15972705481 | I114: jin.zhang@everestmedicines.com
A115: CSO00000114 | B115: 万鹏 | C115: 男 | D115: 宜昌市中心人民医院 | E115: =VLOOKUP($D115,[1]医生名单!$M:$N,2,0) -> H4205001 | F115: ICU | G115: 主任医师 | H115: 18671740020 | I115: jin.zhang@everestmedicines.com
A116: CSO00000115 | B116: 张新黎 | C116: 女 | D116: 宜昌市中心人民医院 | E116: =VLOOKUP($D116,[1]医生名单!$M:$N,2,0) -> H4205001 | F116: ICU | G116: 主任医师 | H116: 13997699724 | I116: jin.zhang@everestmedicines.com
A117: CSO00000116 | B117: 李文田 | C117: 男 | D117: 宜昌市中心人民医院 | E117: =VLOOKUP($D117,[1]医生名单!$M:$N,2,0) -> H4205001 | F117: 呼吸ICU | G117: 副主任医师 | H117: 15872672621 | I117: jin.zhang@everestmedicines.com
A118: CSO00000117 | B118: 曹路 | C118: 男 | D118: 宜昌市中心人民医院 | E118: =VLOOKUP($D118,[1]医生名单!$M:$N,2,0) -> H4205001 | F118: 呼吸ICU | G118: 副主任医师 | H118: 13545751633 | I118: jin.zhang@everestmedicines.com
A119: CSO00000118 | B119: 李朋 | C119: 男 | D119: 宜昌市中心人民医院 | E119: =VLOOKUP($D119,[1]医生名单!$M:$N,2,0) -> H4205001 | F119: 呼吸ICU | G119: 主治医师 | H119: 15997596372 | I119: jin.zhang@everestmedicines.com
A120: CSO00000119 | B120: 牟干 | C120: 男 | D120: 宜昌市中心人民医院 | E120: =VLOOKUP($D120,[1]医生名单!$M:$N,2,0) -> H4205001 | F120: 呼吸ICU | G120: 主治医师 | H120: 15672485808 | I120: jin.zhang@everestmedicines.com
A121: CSO00000120 | B121: 向光明 | C121: 男 | D121: 宜昌市中心人民医院 | E121: =VLOOKUP($D121,[1]医生名单!$M:$N,2,0) -> H4205001 | F121: 呼吸内科 | G121: 主任医师 | H121: 13986755610 | I121: jin.zhang@everestmedicines.com
A122: CSO00000121 | B122: 苏建 | C122: 男 | D122: 宜昌市中心人民医院 | E122: =VLOOKUP($D122,[1]医生名单!$M:$N,2,0) -> H4205001 | F122: 呼吸内科 | G122: 副主任医师 | H122: 15897502271 | I122: jin.zhang@everestmedicines.com
A123: CSO00000122 | B123: 王海燕 | C123: 女 | D123: 宜昌市中心人民医院 | E123: =VLOOKUP($D123,[1]医生名单!$M:$N,2,0) -> H4205001 | F123: 血液内科 | G123: 副主任医师 | H123: 15872639122 | I123: jin.zhang@everestmedicines.com
A124: CSO00000123 | B124: 郑静 | C124: 男 | D124: 宜昌市中心人民医院 | E124: =VLOOKUP($D124,[1]医生名单!$M:$N,2,0) -> H4205001 | F124: 血液内科 | G124: 副主任医师 | H124: 18871799726 | I124: jin.zhang@everestmedicines.com
...
