Workbook

Sheet T&E_
B2: CC1 | C2: CC2 | D2: Dept Name | E2: FP&A L1 | F2: FP&A L2 | G2: Brand | H2: Year | I2: Data Type | J2: Mgt Report L1 | K2: Mgt Report L2 | L2: Mgt Report L3 | M2: Mgt Report L4 | N2: Mgt Report L5 | O2: Mgt Report L6 | P2: CN Name | Q2: Note1 | R2: Note2 | S2: Jan | T2: Feb | U2: Mar | V2: Apr | W2: May | X2: Jun | Y2: Jul | Z2: Aug | AA2: Sep | AB2: Oct | AC2: Nov | AD2: Dec | AE2: FY | AG2: Totals | AI2: Q1 | AJ2: Q2 | AK2: Q3 | AL2: Q4 | AM2: Total | AN2: check | AP2: 1H | AQ2: 2H | AR2: check
B3: C110101101 | C3: 10101101 | D3: 北一区-Xerava | E3: T&E | F3: T&E | G3: Xerava | H3: 2026 | I3: Budget | J3: Commercial | K3: Mainland | L3: CPO Operations | M3: Sales Team | N3: North 1 | O3: North 1 | P3: 北一区 | S3: =SUMIFS('Sales HC by Dept & T&E Segment'!V:V,'Sales HC by Dept & T&E Segment'!$F:$F,$P3,'Sales HC by Dept & T&E Segment'!$G:$G,$G3) -> 140000 | T3: =SUMIFS('Sales HC by Dept & T&E Segment'!W:W,'Sales HC by Dept & T&E Segment'!$F:$F,$P3,'Sales HC by Dept & T&E Segment'!$G:$G,$G3) -> 140000 | U3: =SUMIFS('Sales HC by Dept & T&E Segment'!X:X,'Sales HC by Dept & T&E Segment'!$F:$F,$P3,'Sales HC by Dept & T&E Segment'!$G:$G,$G3) -> 140000 | V3: =SUMIFS('Sales HC by Dept & T&E Segment'!Y:Y,'Sales HC by Dept & T&E Segment'!$F:$F,$P3,'Sales HC by Dept & T&E Segment'!$G:$G,$G3) -> 140000 | W3: =SUMIFS('Sales HC by Dept & T&E Segment'!Z:Z,'Sales HC by Dept & T&E Segment'!$F:$F,$P3,'Sales HC by Dept & T&E Segment'!$G:$G,$G3) -> 140000 | X3: =SUMIFS('Sales HC by Dept & T&E Segment'!AA:AA,'Sales HC by Dept & T&E Segment'!$F:$F,$P3,'Sales HC by Dept & T&E Segment'!$G:$G,$G3) -> 140000 | Y3: =SUMIFS('Sales HC by Dept & T&E Segment'!AB:AB,'Sales HC by Dept & T&E Segment'!$F:$F,$P3,'Sales HC by Dept & T&E Segment'!$G:$G,$G3) -> 140000 | Z3: =SUMIFS('Sales HC by Dept & T&E Segment'!AC:AC,'Sales HC by Dept & T&E Segment'!$F:$F,$P3,'Sales HC by Dept & T&E Segment'!$G:$G,$G3) -> 140000 | AA3: =SUMIFS('Sales HC by Dept & T&E Segment'!AD:AD,'Sales HC by Dept & T&E Segment'!$F:$F,$P3,'Sales HC by Dept & T&E Segment'!$G:$G,$G3) -> 140000 | AB3: =SUMIFS('Sales HC by Dept & T&E Segment'!AE:AE,'Sales HC by Dept & T&E Segment'!$F:$F,$P3,'Sales HC by Dept & T&E Segment'!$G:$G,$G3) -> 140000 | AC3: =SUMIFS('Sales HC by Dept & T&E Segment'!AF:AF,'Sales HC by Dept & T&E Segment'!$F:$F,$P3,'Sales HC by Dept & T&E Segment'!$G:$G,$G3) -> 140000 | AD3: =SUMIFS('Sales HC by Dept & T&E Segment'!AG:AG,'Sales HC by Dept & T&E Segment'!$F:$F,$P3,'Sales HC by Dept & T&E Segment'!$G:$G,$G3) -> 140000 | AE3: =SUM(S3:AD3) -> 1680000 | AI3: =SUM(S3:U3) -> 420000 | AJ3: =SUM(V3:X3) -> 420000 | AK3: =SUM(Y3:AA3) -> 420000 | AL3: =SUM(AB3:AD3) -> 420000 | AM3: =SUM(AI3:AL3) -> 1680000 | AN3: =AM3-AE3 -> 0 | AP3: =SUM(AI3:AJ3) -> 840000 | AQ3: =SUM(AK3:AL3) -> 840000 | AR3: =AP3+AQ3-AM3 -> 0
B4: C110101201 | C4: 10101201 | D4: 北二区-Xerava | E4: T&E | F4: T&E | G4: Xerava | H4: 2026 | I4: Budget | J4: Commercial | K4: Mainland | L4: CPO Operations | M4: Sales Team | N4: North 2 | O4: North 2 | P4: 北二区 | S4: =SUMIFS('Sales HC by Dept & T&E Segment'!V:V,'Sales HC by Dept & T&E Segment'!$F:$F,$P4,'Sales HC by Dept & T&E Segment'!$G:$G,$G4) -> 56000 | T4: =SUMIFS('Sales HC by Dept & T&E Segment'!W:W,'Sales HC by Dept & T&E Segment'!$F:$F,$P4,'Sales HC by Dept & T&E Segment'!$G:$G,$G4) -> 56000 | U4: =SUMIFS('Sales HC by Dept & T&E Segment'!X:X,'Sales HC by Dept & T&E Segment'!$F:$F,$P4,'Sales HC by Dept & T&E Segment'!$G:$G,$G4) -> 56000 | V4: =SUMIFS('Sales HC by Dept & T&E Segment'!Y:Y,'Sales HC by Dept & T&E Segment'!$F:$F,$P4,'Sales HC by Dept & T&E Segment'!$G:$G,$G4) -> 56000 | W4: =SUMIFS('Sales HC by Dept & T&E Segment'!Z:Z,'Sales HC by Dept & T&E Segment'!$F:$F,$P4,'Sales HC by Dept & T&E Segment'!$G:$G,$G4) -> 56000 | X4: =SUMIFS('Sales HC by Dept & T&E Segment'!AA:AA,'Sales HC by Dept & T&E Segment'!$F:$F,$P4,'Sales HC by Dept & T&E Segment'!$G:$G,$G4) -> 56000 | Y4: =SUMIFS('Sales HC by Dept & T&E Segment'!AB:AB,'Sales HC by Dept & T&E Segment'!$F:$F,$P4,'Sales HC by Dept & T&E Segment'!$G:$G,$G4) -> 56000 | Z4: =SUMIFS('Sales HC by Dept & T&E Segment'!AC:AC,'Sales HC by Dept & T&E Segment'!$F:$F,$P4,'Sales HC by Dept & T&E Segment'!$G:$G,$G4) -> 56000 | AA4: =SUMIFS('Sales HC by Dept & T&E Segment'!AD:AD,'Sales HC by Dept & T&E Segment'!$F:$F,$P4,'Sales HC by Dept & T&E Segment'!$G:$G,$G4) -> 56000 | AB4: =SUMIFS('Sales HC by Dept & T&E Segment'!AE:AE,'Sales HC by Dept & T&E Segment'!$F:$F,$P4,'Sales HC by Dept & T&E Segment'!$G:$G,$G4) -> 56000 | AC4: =SUMIFS('Sales HC by Dept & T&E Segment'!AF:AF,'Sales HC by Dept & T&E Segment'!$F:$F,$P4,'Sales HC by Dept & T&E Segment'!$G:$G,$G4) -> 56000 | AD4: =SUMIFS('Sales HC by Dept & T&E Segment'!AG:AG,'Sales HC by Dept & T&E Segment'!$F:$F,$P4,'Sales HC by Dept & T&E Segment'!$G:$G,$G4) -> 56000 | AE4: =SUM(S4:AD4) -> 672000 | AI4: =SUM(S4:U4) -> 168000 | AJ4: =SUM(V4:X4) -> 168000 | AK4: =SUM(Y4:AA4) -> 168000 | AL4: =SUM(AB4:AD4) -> 168000 | AM4: =SUM(AI4:AL4) -> 672000 | AN4: =AM4-AE4 -> 0 | AP4: =SUM(AI4:AJ4) -> 336000 | AQ4: =SUM(AK4:AL4) -> 336000 | AR4: =AP4+AQ4-AM4 -> 0
B5: C110101301 | C5: 10101301 | D5: 北三区-Xerava | E5: T&E | F5: T&E | G5: Xerava | H5: 2026 | I5: Budget | J5: Commercial | K5: Mainland | L5: CPO Operations | M5: Sales Team | N5: North 3 | O5: North 3 | P5: 北三区 | S5: =SUMIFS('Sales HC by Dept & T&E Segment'!V:V,'Sales HC by Dept & T&E Segment'!$F:$F,$P5,'Sales HC by Dept & T&E Segment'!$G:$G,$G5) -> 92000 | T5: =SUMIFS('Sales HC by Dept & T&E Segment'!W:W,'Sales HC by Dept & T&E Segment'!$F:$F,$P5,'Sales HC by Dept & T&E Segment'!$G:$G,$G5) -> 92000 | U5: =SUMIFS('Sales HC by Dept & T&E Segment'!X:X,'Sales HC by Dept & T&E Segment'!$F:$F,$P5,'Sales HC by Dept & T&E Segment'!$G:$G,$G5) -> 92000 | V5: =SUMIFS('Sales HC by Dept & T&E Segment'!Y:Y,'Sales HC by Dept & T&E Segment'!$F:$F,$P5,'Sales HC by Dept & T&E Segment'!$G:$G,$G5) -> 92000 | W5: =SUMIFS('Sales HC by Dept & T&E Segment'!Z:Z,'Sales HC by Dept & T&E Segment'!$F:$F,$P5,'Sales HC by Dept & T&E Segment'!$G:$G,$G5) -> 92000 | X5: =SUMIFS('Sales HC by Dept & T&E Segment'!AA:AA,'Sales HC by Dept & T&E Segment'!$F:$F,$P5,'Sales HC by Dept & T&E Segment'!$G:$G,$G5) -> 92000 | Y5: =SUMIFS('Sales HC by Dept & T&E Segment'!AB:AB,'Sales HC by Dept & T&E Segment'!$F:$F,$P5,'Sales HC by Dept & T&E Segment'!$G:$G,$G5) -> 92000 | Z5: =SUMIFS('Sales HC by Dept & T&E Segment'!AC:AC,'Sales HC by Dept & T&E Segment'!$F:$F,$P5,'Sales HC by Dept & T&E Segment'!$G:$G,$G5) -> 92000 | AA5: =SUMIFS('Sales HC by Dept & T&E Segment'!AD:AD,'Sales HC by Dept & T&E Segment'!$F:$F,$P5,'Sales HC by Dept & T&E Segment'!$G:$G,$G5) -> 92000 | AB5: =SUMIFS('Sales HC by Dept & T&E Segment'!AE:AE,'Sales HC by Dept & T&E Segment'!$F:$F,$P5,'Sales HC by Dept & T&E Segment'!$G:$G,$G5) -> 92000 | AC5: =SUMIFS('Sales HC by Dept & T&E Segment'!AF:AF,'Sales HC by Dept & T&E Segment'!$F:$F,$P5,'Sales HC by Dept & T&E Segment'!$G:$G,$G5) -> 92000 | AD5: =SUMIFS('Sales HC by Dept & T&E Segment'!AG:AG,'Sales HC by Dept & T&E Segment'!$F:$F,$P5,'Sales HC by Dept & T&E Segment'!$G:$G,$G5) -> 92000 | AE5: =SUM(S5:AD5) -> 1104000 | AI5: =SUM(S5:U5) -> 276000 | AJ5: =SUM(V5:X5) -> 276000 | AK5: =SUM(Y5:AA5) -> 276000 | AL5: =SUM(AB5:AD5) -> 276000 | AM5: =SUM(AI5:AL5) -> 1104000 | AN5: =AM5-AE5 -> 0 | AP5: =SUM(AI5:AJ5) -> 552000 | AQ5: =SUM(AK5:AL5) -> 552000 | AR5: =AP5+AQ5-AM5 -> 0
B6: C110102101 | C6: 10102101 | D6: 东一区-Xerava | E6: T&E | F6: T&E | G6: Xerava | H6: 2026 | I6: Budget | J6: Commercial | K6: Mainland | L6: CPO Operations | M6: Sales Team | N6: East 1 | O6: East 1 | P6: 东一区 | S6: =SUMIFS('Sales HC by Dept & T&E Segment'!V:V,'Sales HC by Dept & T&E Segment'!$F:$F,$P6,'Sales HC by Dept & T&E Segment'!$G:$G,$G6) -> 102000 | T6: =SUMIFS('Sales HC by Dept & T&E Segment'!W:W,'Sales HC by Dept & T&E Segment'!$F:$F,$P6,'Sales HC by Dept & T&E Segment'!$G:$G,$G6) -> 102000 | U6: =SUMIFS('Sales HC by Dept & T&E Segment'!X:X,'Sales HC by Dept & T&E Segment'!$F:$F,$P6,'Sales HC by Dept & T&E Segment'!$G:$G,$G6) -> 102000 | V6: =SUMIFS('Sales HC by Dept & T&E Segment'!Y:Y,'Sales HC by Dept & T&E Segment'!$F:$F,$P6,'Sales HC by Dept & T&E Segment'!$G:$G,$G6) -> 102000 | W6: =SUMIFS('Sales HC by Dept & T&E Segment'!Z:Z,'Sales HC by Dept & T&E Segment'!$F:$F,$P6,'Sales HC by Dept & T&E Segment'!$G:$G,$G6) -> 102000 | X6: =SUMIFS('Sales HC by Dept & T&E Segment'!AA:AA,'Sales HC by Dept & T&E Segment'!$F:$F,$P6,'Sales HC by Dept & T&E Segment'!$G:$G,$G6) -> 102000 | Y6: =SUMIFS('Sales HC by Dept & T&E Segment'!AB:AB,'Sales HC by Dept & T&E Segment'!$F:$F,$P6,'Sales HC by Dept & T&E Segment'!$G:$G,$G6) -> 102000 | Z6: =SUMIFS('Sales HC by Dept & T&E Segment'!AC:AC,'Sales HC by Dept & T&E Segment'!$F:$F,$P6,'Sales HC by Dept & T&E Segment'!$G:$G,$G6) -> 102000 | AA6: =SUMIFS('Sales HC by Dept & T&E Segment'!AD:AD,'Sales HC by Dept & T&E Segment'!$F:$F,$P6,'Sales HC by Dept & T&E Segment'!$G:$G,$G6) -> 102000 | AB6: =SUMIFS('Sales HC by Dept & T&E Segment'!AE:AE,'Sales HC by Dept & T&E Segment'!$F:$F,$P6,'Sales HC by Dept & T&E Segment'!$G:$G,$G6) -> 102000 | AC6: =SUMIFS('Sales HC by Dept & T&E Segment'!AF:AF,'Sales HC by Dept & T&E Segment'!$F:$F,$P6,'Sales HC by Dept & T&E Segment'!$G:$G,$G6) -> 102000 | AD6: =SUMIFS('Sales HC by Dept & T&E Segment'!AG:AG,'Sales HC by Dept & T&E Segment'!$F:$F,$P6,'Sales HC by Dept & T&E Segment'!$G:$G,$G6) -> 102000 | AE6: =SUM(S6:AD6) -> 1224000 | AI6: =SUM(S6:U6) -> 306000 | AJ6: =SUM(V6:X6) -> 306000 | AK6: =SUM(Y6:AA6) -> 306000 | AL6: =SUM(AB6:AD6) -> 306000 | AM6: =SUM(AI6:AL6) -> 1224000 | AN6: =AM6-AE6 -> 0 | AP6: =SUM(AI6:AJ6) -> 612000 | AQ6: =SUM(AK6:AL6) -> 612000 | AR6: =AP6+AQ6-AM6 -> 0
B7: C110102201 | C7: 10102201 | D7: 东二区-Xerava | E7: T&E | F7: T&E | G7: Xerava | H7: 2026 | I7: Budget | J7: Commercial | K7: Mainland | L7: CPO Operations | M7: Sales Team | N7: East 2 | O7: East 2 | P7: 东二区 | S7: =SUMIFS('Sales HC by Dept & T&E Segment'!V:V,'Sales HC by Dept & T&E Segment'!$F:$F,$P7,'Sales HC by Dept & T&E Segment'!$G:$G,$G7) -> 107000 | T7: =SUMIFS('Sales HC by Dept & T&E Segment'!W:W,'Sales HC by Dept & T&E Segment'!$F:$F,$P7,'Sales HC by Dept & T&E Segment'!$G:$G,$G7) -> 107000 | U7: =SUMIFS('Sales HC by Dept & T&E Segment'!X:X,'Sales HC by Dept & T&E Segment'!$F:$F,$P7,'Sales HC by Dept & T&E Segment'!$G:$G,$G7) -> 107000 | V7: =SUMIFS('Sales HC by Dept & T&E Segment'!Y:Y,'Sales HC by Dept & T&E Segment'!$F:$F,$P7,'Sales HC by Dept & T&E Segment'!$G:$G,$G7) -> 107000 | W7: =SUMIFS('Sales HC by Dept & T&E Segment'!Z:Z,'Sales HC by Dept & T&E Segment'!$F:$F,$P7,'Sales HC by Dept & T&E Segment'!$G:$G,$G7) -> 107000 | X7: =SUMIFS('Sales HC by Dept & T&E Segment'!AA:AA,'Sales HC by Dept & T&E Segment'!$F:$F,$P7,'Sales HC by Dept & T&E Segment'!$G:$G,$G7) -> 107000 | Y7: =SUMIFS('Sales HC by Dept & T&E Segment'!AB:AB,'Sales HC by Dept & T&E Segment'!$F:$F,$P7,'Sales HC by Dept & T&E Segment'!$G:$G,$G7) -> 107000 | Z7: =SUMIFS('Sales HC by Dept & T&E Segment'!AC:AC,'Sales HC by Dept & T&E Segment'!$F:$F,$P7,'Sales HC by Dept & T&E Segment'!$G:$G,$G7) -> 107000 | AA7: =SUMIFS('Sales HC by Dept & T&E Segment'!AD:AD,'Sales HC by Dept & T&E Segment'!$F:$F,$P7,'Sales HC by Dept & T&E Segment'!$G:$G,$G7) -> 107000 | AB7: =SUMIFS('Sales HC by Dept & T&E Segment'!AE:AE,'Sales HC by Dept & T&E Segment'!$F:$F,$P7,'Sales HC by Dept & T&E Segment'!$G:$G,$G7) -> 107000 | AC7: =SUMIFS('Sales HC by Dept & T&E Segment'!AF:AF,'Sales HC by Dept & T&E Segment'!$F:$F,$P7,'Sales HC by Dept & T&E Segment'!$G:$G,$G7) -> 107000 | AD7: =SUMIFS('Sales HC by Dept & T&E Segment'!AG:AG,'Sales HC by Dept & T&E Segment'!$F:$F,$P7,'Sales HC by Dept & T&E Segment'!$G:$G,$G7) -> 107000 | AE7: =SUM(S7:AD7) -> 1284000 | AI7: =SUM(S7:U7) -> 321000 | AJ7: =SUM(V7:X7) -> 321000 | AK7: =SUM(Y7:AA7) -> 321000 | AL7: =SUM(AB7:AD7) -> 321000 | AM7: =SUM(AI7:AL7) -> 1284000 | AN7: =AM7-AE7 -> 0 | AP7: =SUM(AI7:AJ7) -> 642000 | AQ7: =SUM(AK7:AL7) -> 642000 | AR7: =AP7+AQ7-AM7 -> 0
B8: C110102301 | C8: 10102301 | D8: 东三区-Xerava | E8: T&E | F8: T&E | G8: Xerava | H8: 2026 | I8: Budget | J8: Commercial | K8: Mainland | L8: CPO Operations | M8: Sales Team | N8: East 3 | O8: East 3 | P8: 东三区 | S8: =SUMIFS('Sales HC by Dept & T&E Segment'!V:V,'Sales HC by Dept & T&E Segment'!$F:$F,$P8,'Sales HC by Dept & T&E Segment'!$G:$G,$G8) -> 89000 | T8: =SUMIFS('Sales HC by Dept & T&E Segment'!W:W,'Sales HC by Dept & T&E Segment'!$F:$F,$P8,'Sales HC by Dept & T&E Segment'!$G:$G,$G8) -> 89000 | U8: =SUMIFS('Sales HC by Dept & T&E Segment'!X:X,'Sales HC by Dept & T&E Segment'!$F:$F,$P8,'Sales HC by Dept & T&E Segment'!$G:$G,$G8) -> 89000 | V8: =SUMIFS('Sales HC by Dept & T&E Segment'!Y:Y,'Sales HC by Dept & T&E Segment'!$F:$F,$P8,'Sales HC by Dept & T&E Segment'!$G:$G,$G8) -> 89000 | W8: =SUMIFS('Sales HC by Dept & T&E Segment'!Z:Z,'Sales HC by Dept & T&E Segment'!$F:$F,$P8,'Sales HC by Dept & T&E Segment'!$G:$G,$G8) -> 89000 | X8: =SUMIFS('Sales HC by Dept & T&E Segment'!AA:AA,'Sales HC by Dept & T&E Segment'!$F:$F,$P8,'Sales HC by Dept & T&E Segment'!$G:$G,$G8) -> 89000 | Y8: =SUMIFS('Sales HC by Dept & T&E Segment'!AB:AB,'Sales HC by Dept & T&E Segment'!$F:$F,$P8,'Sales HC by Dept & T&E Segment'!$G:$G,$G8) -> 89000 | Z8: =SUMIFS('Sales HC by Dept & T&E Segment'!AC:AC,'Sales HC by Dept & T&E Segment'!$F:$F,$P8,'Sales HC by Dept & T&E Segment'!$G:$G,$G8) -> 89000 | AA8: =SUMIFS('Sales HC by Dept & T&E Segment'!AD:AD,'Sales HC by Dept & T&E Segment'!$F:$F,$P8,'Sales HC by Dept & T&E Segment'!$G:$G,$G8) -> 89000 | AB8: =SUMIFS('Sales HC by Dept & T&E Segment'!AE:AE,'Sales HC by Dept & T&E Segment'!$F:$F,$P8,'Sales HC by Dept & T&E Segment'!$G:$G,$G8) -> 89000 | AC8: =SUMIFS('Sales HC by Dept & T&E Segment'!AF:AF,'Sales HC by Dept & T&E Segment'!$F:$F,$P8,'Sales HC by Dept & T&E Segment'!$G:$G,$G8) -> 89000 | AD8: =SUMIFS('Sales HC by Dept & T&E Segment'!AG:AG,'Sales HC by Dept & T&E Segment'!$F:$F,$P8,'Sales HC by Dept & T&E Segment'!$G:$G,$G8) -> 89000 | AE8: =SUM(S8:AD8) -> 1068000 | AI8: =SUM(S8:U8) -> 267000 | AJ8: =SUM(V8:X8) -> 267000 | AK8: =SUM(Y8:AA8) -> 267000 | AL8: =SUM(AB8:AD8) -> 267000 | AM8: =SUM(AI8:AL8) -> 1068000 | AN8: =AM8-AE8 -> 0 | AP8: =SUM(AI8:AJ8) -> 534000 | AQ8: =SUM(AK8:AL8) -> 534000 | AR8: =AP8+AQ8-AM8 -> 0
B9: C110103101 | C9: 10103101 | D9: 华中区-Xerava | E9: T&E | F9: T&E | G9: Xerava | H9: 2026 | I9: Budget | J9: Commercial | K9: Mainland | L9: CPO Operations | M9: Sales Team | N9: Central | O9: Central | P9: 华中区 | S9: =SUMIFS('Sales HC by Dept & T&E Segment'!V:V,'Sales HC by Dept & T&E Segment'!$F:$F,$P9,'Sales HC by Dept & T&E Segment'!$G:$G,$G9) -> 100000 | T9: =SUMIFS('Sales HC by Dept & T&E Segment'!W:W,'Sales HC by Dept & T&E Segment'!$F:$F,$P9,'Sales HC by Dept & T&E Segment'!$G:$G,$G9) -> 100000 | U9: =SUMIFS('Sales HC by Dept & T&E Segment'!X:X,'Sales HC by Dept & T&E Segment'!$F:$F,$P9,'Sales HC by Dept & T&E Segment'!$G:$G,$G9) -> 100000 | V9: =SUMIFS('Sales HC by Dept & T&E Segment'!Y:Y,'Sales HC by Dept & T&E Segment'!$F:$F,$P9,'Sales HC by Dept & T&E Segment'!$G:$G,$G9) -> 100000 | W9: =SUMIFS('Sales HC by Dept & T&E Segment'!Z:Z,'Sales HC by Dept & T&E Segment'!$F:$F,$P9,'Sales HC by Dept & T&E Segment'!$G:$G,$G9) -> 100000 | X9: =SUMIFS('Sales HC by Dept & T&E Segment'!AA:AA,'Sales HC by Dept & T&E Segment'!$F:$F,$P9,'Sales HC by Dept & T&E Segment'!$G:$G,$G9) -> 100000 | Y9: =SUMIFS('Sales HC by Dept & T&E Segment'!AB:AB,'Sales HC by Dept & T&E Segment'!$F:$F,$P9,'Sales HC by Dept & T&E Segment'!$G:$G,$G9) -> 100000 | Z9: =SUMIFS('Sales HC by Dept & T&E Segment'!AC:AC,'Sales HC by Dept & T&E Segment'!$F:$F,$P9,'Sales HC by Dept & T&E Segment'!$G:$G,$G9) -> 100000 | AA9: =SUMIFS('Sales HC by Dept & T&E Segment'!AD:AD,'Sales HC by Dept & T&E Segment'!$F:$F,$P9,'Sales HC by Dept & T&E Segment'!$G:$G,$G9) -> 100000 | AB9: =SUMIFS('Sales HC by Dept & T&E Segment'!AE:AE,'Sales HC by Dept & T&E Segment'!$F:$F,$P9,'Sales HC by Dept & T&E Segment'!$G:$G,$G9) -> 100000 | AC9: =SUMIFS('Sales HC by Dept & T&E Segment'!AF:AF,'Sales HC by Dept & T&E Segment'!$F:$F,$P9,'Sales HC by Dept & T&E Segment'!$G:$G,$G9) -> 100000 | AD9: =SUMIFS('Sales HC by Dept & T&E Segment'!AG:AG,'Sales HC by Dept & T&E Segment'!$F:$F,$P9,'Sales HC by Dept & T&E Segment'!$G:$G,$G9) -> 100000 | AE9: =SUM(S9:AD9) -> 1200000 | AI9: =SUM(S9:U9) -> 300000 | AJ9: =SUM(V9:X9) -> 300000 | AK9: =SUM(Y9:AA9) -> 300000 | AL9: =SUM(AB9:AD9) -> 300000 | AM9: =SUM(AI9:AL9) -> 1200000 | AN9: =AM9-AE9 -> 0 | AP9: =SUM(AI9:AJ9) -> 600000 | AQ9: =SUM(AK9:AL9) -> 600000 | AR9: =AP9+AQ9-AM9 -> 0
B10: C110106101 | C10: 10106101 | D10: 东北区-Xerava | E10: T&E | F10: T&E | G10: Xerava | H10: 2026 | I10: Budget | J10: Commercial | K10: Mainland | L10: CPO Operations | M10: Sales Team | N10: Northeast | O10: Northeast | P10: 东北区 | S10: =SUMIFS('Sales HC by Dept & T&E Segment'!V:V,'Sales HC by Dept & T&E Segment'!$F:$F,$P10,'Sales HC by Dept & T&E Segment'!$G:$G,$G10) -> 51000 | T10: =SUMIFS('Sales HC by Dept & T&E Segment'!W:W,'Sales HC by Dept & T&E Segment'!$F:$F,$P10,'Sales HC by Dept & T&E Segment'!$G:$G,$G10) -> 51000 | U10: =SUMIFS('Sales HC by Dept & T&E Segment'!X:X,'Sales HC by Dept & T&E Segment'!$F:$F,$P10,'Sales HC by Dept & T&E Segment'!$G:$G,$G10) -> 51000 | V10: =SUMIFS('Sales HC by Dept & T&E Segment'!Y:Y,'Sales HC by Dept & T&E Segment'!$F:$F,$P10,'Sales HC by Dept & T&E Segment'!$G:$G,$G10) -> 51000 | W10: =SUMIFS('Sales HC by Dept & T&E Segment'!Z:Z,'Sales HC by Dept & T&E Segment'!$F:$F,$P10,'Sales HC by Dept & T&E Segment'!$G:$G,$G10) -> 51000 | X10: =SUMIFS('Sales HC by Dept & T&E Segment'!AA:AA,'Sales HC by Dept & T&E Segment'!$F:$F,$P10,'Sales HC by Dept & T&E Segment'!$G:$G,$G10) -> 51000 | Y10: =SUMIFS('Sales HC by Dept & T&E Segment'!AB:AB,'Sales HC by Dept & T&E Segment'!$F:$F,$P10,'Sales HC by Dept & T&E Segment'!$G:$G,$G10) -> 51000 | Z10: =SUMIFS('Sales HC by Dept & T&E Segment'!AC:AC,'Sales HC by Dept & T&E Segment'!$F:$F,$P10,'Sales HC by Dept & T&E Segment'!$G:$G,$G10) -> 51000 | AA10: =SUMIFS('Sales HC by Dept & T&E Segment'!AD:AD,'Sales HC by Dept & T&E Segment'!$F:$F,$P10,'Sales HC by Dept & T&E Segment'!$G:$G,$G10) -> 51000 | AB10: =SUMIFS('Sales HC by Dept & T&E Segment'!AE:AE,'Sales HC by Dept & T&E Segment'!$F:$F,$P10,'Sales HC by Dept & T&E Segment'!$G:$G,$G10) -> 51000 | AC10: =SUMIFS('Sales HC by Dept & T&E Segment'!AF:AF,'Sales HC by Dept & T&E Segment'!$F:$F,$P10,'Sales HC by Dept & T&E Segment'!$G:$G,$G10) -> 51000 | AD10: =SUMIFS('Sales HC by Dept & T&E Segment'!AG:AG,'Sales HC by Dept & T&E Segment'!$F:$F,$P10,'Sales HC by Dept & T&E Segment'!$G:$G,$G10) -> 51000 | AE10: =SUM(S10:AD10) -> 612000 | AI10: =SUM(S10:U10) -> 153000 | AJ10: =SUM(V10:X10) -> 153000 | AK10: =SUM(Y10:AA10) -> 153000 | AL10: =SUM(AB10:AD10) -> 153000 | AM10: =SUM(AI10:AL10) -> 612000 | AN10: =AM10-AE10 -> 0 | AP10: =SUM(AI10:AJ10) -> 306000 | AQ10: =SUM(AK10:AL10) -> 306000 | AR10: =AP10+AQ10-AM10 -> 0
B11: C110105101 | C11: 10105101 | D11: 南区-Xerava | E11: T&E | F11: T&E | G11: Xerava | H11: 2026 | I11: Budget | J11: Commercial | K11: Mainland | L11: CPO Operations | M11: Sales Team | N11: South | O11: South | P11: 南区 | S11: =SUMIFS('Sales HC by Dept & T&E Segment'!V:V,'Sales HC by Dept & T&E Segment'!$F:$F,$P11,'Sales HC by Dept & T&E Segment'!$G:$G,$G11) -> 120000 | T11: =SUMIFS('Sales HC by Dept & T&E Segment'!W:W,'Sales HC by Dept & T&E Segment'!$F:$F,$P11,'Sales HC by Dept & T&E Segment'!$G:$G,$G11) -> 120000 | U11: =SUMIFS('Sales HC by Dept & T&E Segment'!X:X,'Sales HC by Dept & T&E Segment'!$F:$F,$P11,'Sales HC by Dept & T&E Segment'!$G:$G,$G11) -> 120000 | V11: =SUMIFS('Sales HC by Dept & T&E Segment'!Y:Y,'Sales HC by Dept & T&E Segment'!$F:$F,$P11,'Sales HC by Dept & T&E Segment'!$G:$G,$G11) -> 120000 | W11: =SUMIFS('Sales HC by Dept & T&E Segment'!Z:Z,'Sales HC by Dept & T&E Segment'!$F:$F,$P11,'Sales HC by Dept & T&E Segment'!$G:$G,$G11) -> 120000 | X11: =SUMIFS('Sales HC by Dept & T&E Segment'!AA:AA,'Sales HC by Dept & T&E Segment'!$F:$F,$P11,'Sales HC by Dept & T&E Segment'!$G:$G,$G11) -> 120000 | Y11: =SUMIFS('Sales HC by Dept & T&E Segment'!AB:AB,'Sales HC by Dept & T&E Segment'!$F:$F,$P11,'Sales HC by Dept & T&E Segment'!$G:$G,$G11) -> 120000 | Z11: =SUMIFS('Sales HC by Dept & T&E Segment'!AC:AC,'Sales HC by Dept & T&E Segment'!$F:$F,$P11,'Sales HC by Dept & T&E Segment'!$G:$G,$G11) -> 120000 | AA11: =SUMIFS('Sales HC by Dept & T&E Segment'!AD:AD,'Sales HC by Dept & T&E Segment'!$F:$F,$P11,'Sales HC by Dept & T&E Segment'!$G:$G,$G11) -> 120000 | AB11: =SUMIFS('Sales HC by Dept & T&E Segment'!AE:AE,'Sales HC by Dept & T&E Segment'!$F:$F,$P11,'Sales HC by Dept & T&E Segment'!$G:$G,$G11) -> 120000 | AC11: =SUMIFS('Sales HC by Dept & T&E Segment'!AF:AF,'Sales HC by Dept & T&E Segment'!$F:$F,$P11,'Sales HC by Dept & T&E Segment'!$G:$G,$G11) -> 120000 | AD11: =SUMIFS('Sales HC by Dept & T&E Segment'!AG:AG,'Sales HC by Dept & T&E Segment'!$F:$F,$P11,'Sales HC by Dept & T&E Segment'!$G:$G,$G11) -> 120000 | AE11: =SUM(S11:AD11) -> 1440000 | AI11: =SUM(S11:U11) -> 360000 | AJ11: =SUM(V11:X11) -> 360000 | AK11: =SUM(Y11:AA11) -> 360000 | AL11: =SUM(AB11:AD11) -> 360000 | AM11: =SUM(AI11:AL11) -> 1440000 | AN11: =AM11-AE11 -> 0 | AP11: =SUM(AI11:AJ11) -> 720000 | AQ11: =SUM(AK11:AL11) -> 720000 | AR11: =AP11+AQ11-AM11 -> 0
B12: C110107101 | C12: 10107101 | D12: 西区-Xerava | E12: T&E | F12: T&E | G12: Xerava | H12: 2026 | I12: Budget | J12: Commercial | K12: Mainland | L12: CPO Operations | M12: Sales Team | N12: West | O12: West | P12: 西区 | S12: =SUMIFS('Sales HC by Dept & T&E Segment'!V:V,'Sales HC by Dept & T&E Segment'!$F:$F,$P12,'Sales HC by Dept & T&E Segment'!$G:$G,$G12) -> 74000 | T12: =SUMIFS('Sales HC by Dept & T&E Segment'!W:W,'Sales HC by Dept & T&E Segment'!$F:$F,$P12,'Sales HC by Dept & T&E Segment'!$G:$G,$G12) -> 74000 | U12: =SUMIFS('Sales HC by Dept & T&E Segment'!X:X,'Sales HC by Dept & T&E Segment'!$F:$F,$P12,'Sales HC by Dept & T&E Segment'!$G:$G,$G12) -> 74000 | V12: =SUMIFS('Sales HC by Dept & T&E Segment'!Y:Y,'Sales HC by Dept & T&E Segment'!$F:$F,$P12,'Sales HC by Dept & T&E Segment'!$G:$G,$G12) -> 74000 | W12: =SUMIFS('Sales HC by Dept & T&E Segment'!Z:Z,'Sales HC by Dept & T&E Segment'!$F:$F,$P12,'Sales HC by Dept & T&E Segment'!$G:$G,$G12) -> 74000 | X12: =SUMIFS('Sales HC by Dept & T&E Segment'!AA:AA,'Sales HC by Dept & T&E Segment'!$F:$F,$P12,'Sales HC by Dept & T&E Segment'!$G:$G,$G12) -> 74000 | Y12: =SUMIFS('Sales HC by Dept & T&E Segment'!AB:AB,'Sales HC by Dept & T&E Segment'!$F:$F,$P12,'Sales HC by Dept & T&E Segment'!$G:$G,$G12) -> 74000 | Z12: =SUMIFS('Sales HC by Dept & T&E Segment'!AC:AC,'Sales HC by Dept & T&E Segment'!$F:$F,$P12,'Sales HC by Dept & T&E Segment'!$G:$G,$G12) -> 74000 | AA12: =SUMIFS('Sales HC by Dept & T&E Segment'!AD:AD,'Sales HC by Dept & T&E Segment'!$F:$F,$P12,'Sales HC by Dept & T&E Segment'!$G:$G,$G12) -> 74000 | AB12: =SUMIFS('Sales HC by Dept & T&E Segment'!AE:AE,'Sales HC by Dept & T&E Segment'!$F:$F,$P12,'Sales HC by Dept & T&E Segment'!$G:$G,$G12) -> 74000 | AC12: =SUMIFS('Sales HC by Dept & T&E Segment'!AF:AF,'Sales HC by Dept & T&E Segment'!$F:$F,$P12,'Sales HC by Dept & T&E Segment'!$G:$G,$G12) -> 74000 | AD12: =SUMIFS('Sales HC by Dept & T&E Segment'!AG:AG,'Sales HC by Dept & T&E Segment'!$F:$F,$P12,'Sales HC by Dept & T&E Segment'!$G:$G,$G12) -> 74000 | AE12: =SUM(S12:AD12) -> 888000 | AG12: =SUM(AE3:AE12) -> 11172000 | AH12: =AG12-'Sales HC by Dept & T&E Segment'!S41 -> 0 | AI12: =SUM(S12:U12) -> 222000 | AJ12: =SUM(V12:X12) -> 222000 | AK12: =SUM(Y12:AA12) -> 222000 | AL12: =SUM(AB12:AD12) -> 222000 | AM12: =SUM(AI12:AL12) -> 888000 | AN12: =AM12-AE12 -> 0 | AP12: =SUM(AI12:AJ12) -> 444000 | AQ12: =SUM(AK12:AL12) -> 444000 | AR12: =AP12+AQ12-AM12 -> 0
B13: C110101102 | C13: 10101102 | D13: 北一区-Nefecon | E13: T&E | F13: T&E | G13: Nefecon | H13: 2026 | I13: Budget | J13: Commercial | K13: Mainland | L13: CPO Operations | M13: Sales Team | N13: North 1 | O13: North 1 | P13: 北一区 | S13: =SUMIFS('Sales HC by Dept & T&E Segment'!V:V,'Sales HC by Dept & T&E Segment'!$F:$F,$P13,'Sales HC by Dept & T&E Segment'!$G:$G,$G13) -> 158000 | T13: =SUMIFS('Sales HC by Dept & T&E Segment'!W:W,'Sales HC by Dept & T&E Segment'!$F:$F,$P13,'Sales HC by Dept & T&E Segment'!$G:$G,$G13) -> 158000 | U13: =SUMIFS('Sales HC by Dept & T&E Segment'!X:X,'Sales HC by Dept & T&E Segment'!$F:$F,$P13,'Sales HC by Dept & T&E Segment'!$G:$G,$G13) -> 158000 | V13: =SUMIFS('Sales HC by Dept & T&E Segment'!Y:Y,'Sales HC by Dept & T&E Segment'!$F:$F,$P13,'Sales HC by Dept & T&E Segment'!$G:$G,$G13) -> 178000 | W13: =SUMIFS('Sales HC by Dept & T&E Segment'!Z:Z,'Sales HC by Dept & T&E Segment'!$F:$F,$P13,'Sales HC by Dept & T&E Segment'!$G:$G,$G13) -> 178000 | X13: =SUMIFS('Sales HC by Dept & T&E Segment'!AA:AA,'Sales HC by Dept & T&E Segment'!$F:$F,$P13,'Sales HC by Dept & T&E Segment'!$G:$G,$G13) -> 178000 | Y13: =SUMIFS('Sales HC by Dept & T&E Segment'!AB:AB,'Sales HC by Dept & T&E Segment'!$F:$F,$P13,'Sales HC by Dept & T&E Segment'!$G:$G,$G13) -> 178000 | Z13: =SUMIFS('Sales HC by Dept & T&E Segment'!AC:AC,'Sales HC by Dept & T&E Segment'!$F:$F,$P13,'Sales HC by Dept & T&E Segment'!$G:$G,$G13) -> 178000 | AA13: =SUMIFS('Sales HC by Dept & T&E Segment'!AD:AD,'Sales HC by Dept & T&E Segment'!$F:$F,$P13,'Sales HC by Dept & T&E Segment'!$G:$G,$G13) -> 178000 | AB13: =SUMIFS('Sales HC by Dept & T&E Segment'!AE:AE,'Sales HC by Dept & T&E Segment'!$F:$F,$P13,'Sales HC by Dept & T&E Segment'!$G:$G,$G13) -> 178000 | AC13: =SUMIFS('Sales HC by Dept & T&E Segment'!AF:AF,'Sales HC by Dept & T&E Segment'!$F:$F,$P13,'Sales HC by Dept & T&E Segment'!$G:$G,$G13) -> 178000 | AD13: =SUMIFS('Sales HC by Dept & T&E Segment'!AG:AG,'Sales HC by Dept & T&E Segment'!$F:$F,$P13,'Sales HC by Dept & T&E Segment'!$G:$G,$G13) -> 178000 | AE13: =SUM(S13:AD13) -> 2076000 | AI13: =SUM(S13:U13) -> 474000 | AJ13: =SUM(V13:X13) -> 534000 | AK13: =SUM(Y13:AA13) -> 534000 | AL13: =SUM(AB13:AD13) -> 534000 | AM13: =SUM(AI13:AL13) -> 2076000 | AN13: =AM13-AE13 -> 0 | AP13: =SUM(AI13:AJ13) -> 1008000 | AQ13: =SUM(AK13:AL13) -> 1068000 | AR13: =AP13+AQ13-AM13 -> 0
B14: C110101202 | C14: 10101202 | D14: 北二区-Nefecon | E14: T&E | F14: T&E | G14: Nefecon | H14: 2026 | I14: Budget | J14: Commercial | K14: Mainland | L14: CPO Operations | M14: Sales Team | N14: North 2 | O14: North 2 | P14: 北二区 | S14: =SUMIFS('Sales HC by Dept & T&E Segment'!V:V,'Sales HC by Dept & T&E Segment'!$F:$F,$P14,'Sales HC by Dept & T&E Segment'!$G:$G,$G14) -> 157000 | T14: =SUMIFS('Sales HC by Dept & T&E Segment'!W:W,'Sales HC by Dept & T&E Segment'!$F:$F,$P14,'Sales HC by Dept & T&E Segment'!$G:$G,$G14) -> 157000 | U14: =SUMIFS('Sales HC by Dept & T&E Segment'!X:X,'Sales HC by Dept & T&E Segment'!$F:$F,$P14,'Sales HC by Dept & T&E Segment'!$G:$G,$G14) -> 157000 | V14: =SUMIFS('Sales HC by Dept & T&E Segment'!Y:Y,'Sales HC by Dept & T&E Segment'!$F:$F,$P14,'Sales HC by Dept & T&E Segment'!$G:$G,$G14) -> 172000 | W14: =SUMIFS('Sales HC by Dept & T&E Segment'!Z:Z,'Sales HC by Dept & T&E Segment'!$F:$F,$P14,'Sales HC by Dept & T&E Segment'!$G:$G,$G14) -> 172000 | X14: =SUMIFS('Sales HC by Dept & T&E Segment'!AA:AA,'Sales HC by Dept & T&E Segment'!$F:$F,$P14,'Sales HC by Dept & T&E Segment'!$G:$G,$G14) -> 172000 | Y14: =SUMIFS('Sales HC by Dept & T&E Segment'!AB:AB,'Sales HC by Dept & T&E Segment'!$F:$F,$P14,'Sales HC by Dept & T&E Segment'!$G:$G,$G14) -> 172000 | Z14: =SUMIFS('Sales HC by Dept & T&E Segment'!AC:AC,'Sales HC by Dept & T&E Segment'!$F:$F,$P14,'Sales HC by Dept & T&E Segment'!$G:$G,$G14) -> 172000 | AA14: =SUMIFS('Sales HC by Dept & T&E Segment'!AD:AD,'Sales HC by Dept & T&E Segment'!$F:$F,$P14,'Sales HC by Dept & T&E Segment'!$G:$G,$G14) -> 172000 | AB14: =SUMIFS('Sales HC by Dept & T&E Segment'!AE:AE,'Sales HC by Dept & T&E Segment'!$F:$F,$P14,'Sales HC by Dept & T&E Segment'!$G:$G,$G14) -> 172000 | AC14: =SUMIFS('Sales HC by Dept & T&E Segment'!AF:AF,'Sales HC by Dept & T&E Segment'!$F:$F,$P14,'Sales HC by Dept & T&E Segment'!$G:$G,$G14) -> 172000 | AD14: =SUMIFS('Sales HC by Dept & T&E Segment'!AG:AG,'Sales HC by Dept & T&E Segment'!$F:$F,$P14,'Sales HC by Dept & T&E Segment'!$G:$G,$G14) -> 172000 | AE14: =SUM(S14:AD14) -> 2019000 | AI14: =SUM(S14:U14) -> 471000 | AJ14: =SUM(V14:X14) -> 516000 | AK14: =SUM(Y14:AA14) -> 516000 | AL14: =SUM(AB14:AD14) -> 516000 | AM14: =SUM(AI14:AL14) -> 2019000 | AN14: =AM14-AE14 -> 0 | AP14: =SUM(AI14:AJ14) -> 987000 | AQ14: =SUM(AK14:AL14) -> 1032000 | AR14: =AP14+AQ14-AM14 -> 0
B15: C110101302 | C15: 10101302 | D15: 北三区-Nefecon | E15: T&E | F15: T&E | G15: Nefecon | H15: 2026 | I15: Budget | J15: Commercial | K15: Mainland | L15: CPO Operations | M15: Sales Team | N15: North 3 | O15: North 3 | P15: 北三区 | S15: =SUMIFS('Sales HC by Dept & T&E Segment'!V:V,'Sales HC by Dept & T&E Segment'!$F:$F,$P15,'Sales HC by Dept & T&E Segment'!$G:$G,$G15) -> 175000 | T15: =SUMIFS('Sales HC by Dept & T&E Segment'!W:W,'Sales HC by Dept & T&E Segment'!$F:$F,$P15,'Sales HC by Dept & T&E Segment'!$G:$G,$G15) -> 175000 | U15: =SUMIFS('Sales HC by Dept & T&E Segment'!X:X,'Sales HC by Dept & T&E Segment'!$F:$F,$P15,'Sales HC by Dept & T&E Segment'!$G:$G,$G15) -> 175000 | V15: =SUMIFS('Sales HC by Dept & T&E Segment'!Y:Y,'Sales HC by Dept & T&E Segment'!$F:$F,$P15,'Sales HC by Dept & T&E Segment'!$G:$G,$G15) -> 190000 | W15: =SUMIFS('Sales HC by Dept & T&E Segment'!Z:Z,'Sales HC by Dept & T&E Segment'!$F:$F,$P15,'Sales HC by Dept & T&E Segment'!$G:$G,$G15) -> 190000 | X15: =SUMIFS('Sales HC by Dept & T&E Segment'!AA:AA,'Sales HC by Dept & T&E Segment'!$F:$F,$P15,'Sales HC by Dept & T&E Segment'!$G:$G,$G15) -> 190000 | Y15: =SUMIFS('Sales HC by Dept & T&E Segment'!AB:AB,'Sales HC by Dept & T&E Segment'!$F:$F,$P15,'Sales HC by Dept & T&E Segment'!$G:$G,$G15) -> 190000 | Z15: =SUMIFS('Sales HC by Dept & T&E Segment'!AC:AC,'Sales HC by Dept & T&E Segment'!$F:$F,$P15,'Sales HC by Dept & T&E Segment'!$G:$G,$G15) -> 190000 | AA15: =SUMIFS('Sales HC by Dept & T&E Segment'!AD:AD,'Sales HC by Dept & T&E Segment'!$F:$F,$P15,'Sales HC by Dept & T&E Segment'!$G:$G,$G15) -> 190000 | AB15: =SUMIFS('Sales HC by Dept & T&E Segment'!AE:AE,'Sales HC by Dept & T&E Segment'!$F:$F,$P15,'Sales HC by Dept & T&E Segment'!$G:$G,$G15) -> 190000 | AC15: =SUMIFS('Sales HC by Dept & T&E Segment'!AF:AF,'Sales HC by Dept & T&E Segment'!$F:$F,$P15,'Sales HC by Dept & T&E Segment'!$G:$G,$G15) -> 190000 | AD15: =SUMIFS('Sales HC by Dept & T&E Segment'!AG:AG,'Sales HC by Dept & T&E Segment'!$F:$F,$P15,'Sales HC by Dept & T&E Segment'!$G:$G,$G15) -> 190000 | AE15: =SUM(S15:AD15) -> 2235000 | AI15: =SUM(S15:U15) -> 525000 | AJ15: =SUM(V15:X15) -> 570000 | AK15: =SUM(Y15:AA15) -> 570000 | AL15: =SUM(AB15:AD15) -> 570000 | AM15: =SUM(AI15:AL15) -> 2235000 | AN15: =AM15-AE15 -> 0 | AP15: =SUM(AI15:AJ15) -> 1095000 | AQ15: =SUM(AK15:AL15) -> 1140000 | AR15: =AP15+AQ15-AM15 -> 0
B16: C110102102 | C16: 10102102 | D16: 东一区-Nefecon | E16: T&E | F16: T&E | G16: Nefecon | H16: 2026 | I16: Budget | J16: Commercial | K16: Mainland | L16: CPO Operations | M16: Sales Team | N16: East 1 | O16: East 1 | P16: 东一区 | S16: =SUMIFS('Sales HC by Dept & T&E Segment'!V:V,'Sales HC by Dept & T&E Segment'!$F:$F,$P16,'Sales HC by Dept & T&E Segment'!$G:$G,$G16) -> 178000 | T16: =SUMIFS('Sales HC by Dept & T&E Segment'!W:W,'Sales HC by Dept & T&E Segment'!$F:$F,$P16,'Sales HC by Dept & T&E Segment'!$G:$G,$G16) -> 178000 | U16: =SUMIFS('Sales HC by Dept & T&E Segment'!X:X,'Sales HC by Dept & T&E Segment'!$F:$F,$P16,'Sales HC by Dept & T&E Segment'!$G:$G,$G16) -> 178000 | V16: =SUMIFS('Sales HC by Dept & T&E Segment'!Y:Y,'Sales HC by Dept & T&E Segment'!$F:$F,$P16,'Sales HC by Dept & T&E Segment'!$G:$G,$G16) -> 203000 | W16: =SUMIFS('Sales HC by Dept & T&E Segment'!Z:Z,'Sales HC by Dept & T&E Segment'!$F:$F,$P16,'Sales HC by Dept & T&E Segment'!$G:$G,$G16) -> 203000 | X16: =SUMIFS('Sales HC by Dept & T&E Segment'!AA:AA,'Sales HC by Dept & T&E Segment'!$F:$F,$P16,'Sales HC by Dept & T&E Segment'!$G:$G,$G16) -> 203000 | Y16: =SUMIFS('Sales HC by Dept & T&E Segment'!AB:AB,'Sales HC by Dept & T&E Segment'!$F:$F,$P16,'Sales HC by Dept & T&E Segment'!$G:$G,$G16) -> 203000 | Z16: =SUMIFS('Sales HC by Dept & T&E Segment'!AC:AC,'Sales HC by Dept & T&E Segment'!$F:$F,$P16,'Sales HC by Dept & T&E Segment'!$G:$G,$G16) -> 203000 | AA16: =SUMIFS('Sales HC by Dept & T&E Segment'!AD:AD,'Sales HC by Dept & T&E Segment'!$F:$F,$P16,'Sales HC by Dept & T&E Segment'!$G:$G,$G16) -> 203000 | AB16: =SUMIFS('Sales HC by Dept & T&E Segment'!AE:AE,'Sales HC by Dept & T&E Segment'!$F:$F,$P16,'Sales HC by Dept & T&E Segment'!$G:$G,$G16) -> 203000 | AC16: =SUMIFS('Sales HC by Dept & T&E Segment'!AF:AF,'Sales HC by Dept & T&E Segment'!$F:$F,$P16,'Sales HC by Dept & T&E Segment'!$G:$G,$G16) -> 203000 | AD16: =SUMIFS('Sales HC by Dept & T&E Segment'!AG:AG,'Sales HC by Dept & T&E Segment'!$F:$F,$P16,'Sales HC by Dept & T&E Segment'!$G:$G,$G16) -> 203000 | AE16: =SUM(S16:AD16) -> 2361000 | AI16: =SUM(S16:U16) -> 534000 | AJ16: =SUM(V16:X16) -> 609000 | AK16: =SUM(Y16:AA16) -> 609000 | AL16: =SUM(AB16:AD16) -> 609000 | AM16: =SUM(AI16:AL16) -> 2361000 | AN16: =AM16-AE16 -> 0 | AP16: =SUM(AI16:AJ16) -> 1143000 | AQ16: =SUM(AK16:AL16) -> 1218000 | AR16: =AP16+AQ16-AM16 -> 0
B17: C110102202 | C17: 10102202 | D17: 东二区-Nefecon | E17: T&E | F17: T&E | G17: Nefecon | H17: 2026 | I17: Budget | J17: Commercial | K17: Mainland | L17: CPO Operations | M17: Sales Team | N17: East 2 | O17: East 2 | P17: 东二区 | S17: =SUMIFS('Sales HC by Dept & T&E Segment'!V:V,'Sales HC by Dept & T&E Segment'!$F:$F,$P17,'Sales HC by Dept & T&E Segment'!$G:$G,$G17) -> 265000 | T17: =SUMIFS('Sales HC by Dept & T&E Segment'!W:W,'Sales HC by Dept & T&E Segment'!$F:$F,$P17,'Sales HC by Dept & T&E Segment'!$G:$G,$G17) -> 265000 | U17: =SUMIFS('Sales HC by Dept & T&E Segment'!X:X,'Sales HC by Dept & T&E Segment'!$F:$F,$P17,'Sales HC by Dept & T&E Segment'!$G:$G,$G17) -> 265000 | V17: =SUMIFS('Sales HC by Dept & T&E Segment'!Y:Y,'Sales HC by Dept & T&E Segment'!$F:$F,$P17,'Sales HC by Dept & T&E Segment'!$G:$G,$G17) -> 299000 | W17: =SUMIFS('Sales HC by Dept & T&E Segment'!Z:Z,'Sales HC by Dept & T&E Segment'!$F:$F,$P17,'Sales HC by Dept & T&E Segment'!$G:$G,$G17) -> 299000 | X17: =SUMIFS('Sales HC by Dept & T&E Segment'!AA:AA,'Sales HC by Dept & T&E Segment'!$F:$F,$P17,'Sales HC by Dept & T&E Segment'!$G:$G,$G17) -> 299000 | Y17: =SUMIFS('Sales HC by Dept & T&E Segment'!AB:AB,'Sales HC by Dept & T&E Segment'!$F:$F,$P17,'Sales HC by Dept & T&E Segment'!$G:$G,$G17) -> 299000 | Z17: =SUMIFS('Sales HC by Dept & T&E Segment'!AC:AC,'Sales HC by Dept & T&E Segment'!$F:$F,$P17,'Sales HC by Dept & T&E Segment'!$G:$G,$G17) -> 299000 | AA17: =SUMIFS('Sales HC by Dept & T&E Segment'!AD:AD,'Sales HC by Dept & T&E Segment'!$F:$F,$P17,'Sales HC by Dept & T&E Segment'!$G:$G,$G17) -> 299000 | AB17: =SUMIFS('Sales HC by Dept & T&E Segment'!AE:AE,'Sales HC by Dept & T&E Segment'!$F:$F,$P17,'Sales HC by Dept & T&E Segment'!$G:$G,$G17) -> 299000 | AC17: =SUMIFS('Sales HC by Dept & T&E Segment'!AF:AF,'Sales HC by Dept & T&E Segment'!$F:$F,$P17,'Sales HC by Dept & T&E Segment'!$G:$G,$G17) -> 299000 | AD17: =SUMIFS('Sales HC by Dept & T&E Segment'!AG:AG,'Sales HC by Dept & T&E Segment'!$F:$F,$P17,'Sales HC by Dept & T&E Segment'!$G:$G,$G17) -> 299000 | AE17: =SUM(S17:AD17) -> 3486000 | AI17: =SUM(S17:U17) -> 795000 | AJ17: =SUM(V17:X17) -> 897000 | AK17: =SUM(Y17:AA17) -> 897000 | AL17: =SUM(AB17:AD17) -> 897000 | AM17: =SUM(AI17:AL17) -> 3486000 | AN17: =AM17-AE17 -> 0 | AP17: =SUM(AI17:AJ17) -> 1692000 | AQ17: =SUM(AK17:AL17) -> 1794000 | AR17: =AP17+AQ17-AM17 -> 0
B18: C110102302 | C18: 10102302 | D18: 东三区-Nefecon | E18: T&E | F18: T&E | G18: Nefecon | H18: 2026 | I18: Budget | J18: Commercial | K18: Mainland | L18: CPO Operations | M18: Sales Team | N18: East 3 | O18: East 3 | P18: 东三区 | S18: =SUMIFS('Sales HC by Dept & T&E Segment'!V:V,'Sales HC by Dept & T&E Segment'!$F:$F,$P18,'Sales HC by Dept & T&E Segment'!$G:$G,$G18) -> 183000 | T18: =SUMIFS('Sales HC by Dept & T&E Segment'!W:W,'Sales HC by Dept & T&E Segment'!$F:$F,$P18,'Sales HC by Dept & T&E Segment'!$G:$G,$G18) -> 183000 | U18: =SUMIFS('Sales HC by Dept & T&E Segment'!X:X,'Sales HC by Dept & T&E Segment'!$F:$F,$P18,'Sales HC by Dept & T&E Segment'!$G:$G,$G18) -> 183000 | V18: =SUMIFS('Sales HC by Dept & T&E Segment'!Y:Y,'Sales HC by Dept & T&E Segment'!$F:$F,$P18,'Sales HC by Dept & T&E Segment'!$G:$G,$G18) -> 223000 | W18: =SUMIFS('Sales HC by Dept & T&E Segment'!Z:Z,'Sales HC by Dept & T&E Segment'!$F:$F,$P18,'Sales HC by Dept & T&E Segment'!$G:$G,$G18) -> 223000 | X18: =SUMIFS('Sales HC by Dept & T&E Segment'!AA:AA,'Sales HC by Dept & T&E Segment'!$F:$F,$P18,'Sales HC by Dept & T&E Segment'!$G:$G,$G18) -> 223000 | Y18: =SUMIFS('Sales HC by Dept & T&E Segment'!AB:AB,'Sales HC by Dept & T&E Segment'!$F:$F,$P18,'Sales HC by Dept & T&E Segment'!$G:$G,$G18) -> 223000 | Z18: =SUMIFS('Sales HC by Dept & T&E Segment'!AC:AC,'Sales HC by Dept & T&E Segment'!$F:$F,$P18,'Sales HC by Dept & T&E Segment'!$G:$G,$G18) -> 223000 | AA18: =SUMIFS('Sales HC by Dept & T&E Segment'!AD:AD,'Sales HC by Dept & T&E Segment'!$F:$F,$P18,'Sales HC by Dept & T&E Segment'!$G:$G,$G18) -> 223000 | AB18: =SUMIFS('Sales HC by Dept & T&E Segment'!AE:AE,'Sales HC by Dept & T&E Segment'!$F:$F,$P18,'Sales HC by Dept & T&E Segment'!$G:$G,$G18) -> 223000 | AC18: =SUMIFS('Sales HC by Dept & T&E Segment'!AF:AF,'Sales HC by Dept & T&E Segment'!$F:$F,$P18,'Sales HC by Dept & T&E Segment'!$G:$G,$G18) -> 223000 | AD18: =SUMIFS('Sales HC by Dept & T&E Segment'!AG:AG,'Sales HC by Dept & T&E Segment'!$F:$F,$P18,'Sales HC by Dept & T&E Segment'!$G:$G,$G18) -> 223000 | AE18: =SUM(S18:AD18) -> 2556000 | AI18: =SUM(S18:U18) -> 549000 | AJ18: =SUM(V18:X18) -> 669000 | AK18: =SUM(Y18:AA18) -> 669000 | AL18: =SUM(AB18:AD18) -> 669000 | AM18: =SUM(AI18:AL18) -> 2556000 | AN18: =AM18-AE18 -> 0 | AP18: =SUM(AI18:AJ18) -> 1218000 | AQ18: =SUM(AK18:AL18) -> 1338000 | AR18: =AP18+AQ18-AM18 -> 0
B19: C110103102 | C19: 10103102 | D19: 华中区-Nefecon | E19: T&E | F19: T&E | G19: Nefecon | H19: 2026 | I19: Budget | J19: Commercial | K19: Mainland | L19: CPO Operations | M19: Sales Team | N19: Central | O19: Central | P19: 华中区 | S19: =SUMIFS('Sales HC by Dept & T&E Segment'!V:V,'Sales HC by Dept & T&E Segment'!$F:$F,$P19,'Sales HC by Dept & T&E Segment'!$G:$G,$G19) -> 246000 | T19: =SUMIFS('Sales HC by Dept & T&E Segment'!W:W,'Sales HC by Dept & T&E Segment'!$F:$F,$P19,'Sales HC by Dept & T&E Segment'!$G:$G,$G19) -> 246000 | U19: =SUMIFS('Sales HC by Dept & T&E Segment'!X:X,'Sales HC by Dept & T&E Segment'!$F:$F,$P19,'Sales HC by Dept & T&E Segment'!$G:$G,$G19) -> 246000 | V19: =SUMIFS('Sales HC by Dept & T&E Segment'!Y:Y,'Sales HC by Dept & T&E Segment'!$F:$F,$P19,'Sales HC by Dept & T&E Segment'!$G:$G,$G19) -> 300000 | W19: =SUMIFS('Sales HC by Dept & T&E Segment'!Z:Z,'Sales HC by Dept & T&E Segment'!$F:$F,$P19,'Sales HC by Dept & T&E Segment'!$G:$G,$G19) -> 300000 | X19: =SUMIFS('Sales HC by Dept & T&E Segment'!AA:AA,'Sales HC by Dept & T&E Segment'!$F:$F,$P19,'Sales HC by Dept & T&E Segment'!$G:$G,$G19) -> 300000 | Y19: =SUMIFS('Sales HC by Dept & T&E Segment'!AB:AB,'Sales HC by Dept & T&E Segment'!$F:$F,$P19,'Sales HC by Dept & T&E Segment'!$G:$G,$G19) -> 300000 | Z19: =SUMIFS('Sales HC by Dept & T&E Segment'!AC:AC,'Sales HC by Dept & T&E Segment'!$F:$F,$P19,'Sales HC by Dept & T&E Segment'!$G:$G,$G19) -> 300000 | AA19: =SUMIFS('Sales HC by Dept & T&E Segment'!AD:AD,'Sales HC by Dept & T&E Segment'!$F:$F,$P19,'Sales HC by Dept & T&E Segment'!$G:$G,$G19) -> 300000 | AB19: =SUMIFS('Sales HC by Dept & T&E Segment'!AE:AE,'Sales HC by Dept & T&E Segment'!$F:$F,$P19,'Sales HC by Dept & T&E Segment'!$G:$G,$G19) -> 300000 | AC19: =SUMIFS('Sales HC by Dept & T&E Segment'!AF:AF,'Sales HC by Dept & T&E Segment'!$F:$F,$P19,'Sales HC by Dept & T&E Segment'!$G:$G,$G19) -> 300000 | AD19: =SUMIFS('Sales HC by Dept & T&E Segment'!AG:AG,'Sales HC by Dept & T&E Segment'!$F:$F,$P19,'Sales HC by Dept & T&E Segment'!$G:$G,$G19) -> 300000 | AE19: =SUM(S19:AD19) -> 3438000 | AI19: =SUM(S19:U19) -> 738000 | AJ19: =SUM(V19:X19) -> 900000 | AK19: =SUM(Y19:AA19) -> 900000 | AL19: =SUM(AB19:AD19) -> 900000 | AM19: =SUM(AI19:AL19) -> 3438000 | AN19: =AM19-AE19 -> 0 | AP19: =SUM(AI19:AJ19) -> 1638000 | AQ19: =SUM(AK19:AL19) -> 1800000 | AR19: =AP19+AQ19-AM19 -> 0
B20: C110106102 | C20: 10106102 | D20: 东北区-Nefecon | E20: T&E | F20: T&E | G20: Nefecon | H20: 2026 | I20: Budget | J20: Commercial | K20: Mainland | L20: CPO Operations | M20: Sales Team | N20: Northeast | O20: Northeast | P20: 东北区 | S20: =SUMIFS('Sales HC by Dept & T&E Segment'!V:V,'Sales HC by Dept & T&E Segment'!$F:$F,$P20,'Sales HC by Dept & T&E Segment'!$G:$G,$G20) -> 124000 | T20: =SUMIFS('Sales HC by Dept & T&E Segment'!W:W,'Sales HC by Dept & T&E Segment'!$F:$F,$P20,'Sales HC by Dept & T&E Segment'!$G:$G,$G20) -> 124000 | U20: =SUMIFS('Sales HC by Dept & T&E Segment'!X:X,'Sales HC by Dept & T&E Segment'!$F:$F,$P20,'Sales HC by Dept & T&E Segment'!$G:$G,$G20) -> 124000 | V20: =SUMIFS('Sales HC by Dept & T&E Segment'!Y:Y,'Sales HC by Dept & T&E Segment'!$F:$F,$P20,'Sales HC by Dept & T&E Segment'!$G:$G,$G20) -> 159000 | W20: =SUMIFS('Sales HC by Dept & T&E Segment'!Z:Z,'Sales HC by Dept & T&E Segment'!$F:$F,$P20,'Sales HC by Dept & T&E Segment'!$G:$G,$G20) -> 159000 | X20: =SUMIFS('Sales HC by Dept & T&E Segment'!AA:AA,'Sales HC by Dept & T&E Segment'!$F:$F,$P20,'Sales HC by Dept & T&E Segment'!$G:$G,$G20) -> 159000 | Y20: =SUMIFS('Sales HC by Dept & T&E Segment'!AB:AB,'Sales HC by Dept & T&E Segment'!$F:$F,$P20,'Sales HC by Dept & T&E Segment'!$G:$G,$G20) -> 159000 | Z20: =SUMIFS('Sales HC by Dept & T&E Segment'!AC:AC,'Sales HC by Dept & T&E Segment'!$F:$F,$P20,'Sales HC by Dept & T&E Segment'!$G:$G,$G20) -> 159000 | AA20: =SUMIFS('Sales HC by Dept & T&E Segment'!AD:AD,'Sales HC by Dept & T&E Segment'!$F:$F,$P20,'Sales HC by Dept & T&E Segment'!$G:$G,$G20) -> 159000 | AB20: =SUMIFS('Sales HC by Dept & T&E Segment'!AE:AE,'Sales HC by Dept & T&E Segment'!$F:$F,$P20,'Sales HC by Dept & T&E Segment'!$G:$G,$G20) -> 159000 | AC20: =SUMIFS('Sales HC by Dept & T&E Segment'!AF:AF,'Sales HC by Dept & T&E Segment'!$F:$F,$P20,'Sales HC by Dept & T&E Segment'!$G:$G,$G20) -> 159000 | AD20: =SUMIFS('Sales HC by Dept & T&E Segment'!AG:AG,'Sales HC by Dept & T&E Segment'!$F:$F,$P20,'Sales HC by Dept & T&E Segment'!$G:$G,$G20) -> 159000 | AE20: =SUM(S20:AD20) -> 1803000 | AI20: =SUM(S20:U20) -> 372000 | AJ20: =SUM(V20:X20) -> 477000 | AK20: =SUM(Y20:AA20) -> 477000 | AL20: =SUM(AB20:AD20) -> 477000 | AM20: =SUM(AI20:AL20) -> 1803000 | AN20: =AM20-AE20 -> 0 | AP20: =SUM(AI20:AJ20) -> 849000 | AQ20: =SUM(AK20:AL20) -> 954000 | AR20: =AP20+AQ20-AM20 -> 0
B21: C110105102 | C21: 10105102 | D21: 南区-Nefecon | E21: T&E | F21: T&E | G21: Nefecon | H21: 2026 | I21: Budget | J21: Commercial | K21: Mainland | L21: CPO Operations | M21: Sales Team | N21: South | O21: South | P21: 南区 | S21: =SUMIFS('Sales HC by Dept & T&E Segment'!V:V,'Sales HC by Dept & T&E Segment'!$F:$F,$P21,'Sales HC by Dept & T&E Segment'!$G:$G,$G21) -> 226000 | T21: =SUMIFS('Sales HC by Dept & T&E Segment'!W:W,'Sales HC by Dept & T&E Segment'!$F:$F,$P21,'Sales HC by Dept & T&E Segment'!$G:$G,$G21) -> 226000 | U21: =SUMIFS('Sales HC by Dept & T&E Segment'!X:X,'Sales HC by Dept & T&E Segment'!$F:$F,$P21,'Sales HC by Dept & T&E Segment'!$G:$G,$G21) -> 226000 | V21: =SUMIFS('Sales HC by Dept & T&E Segment'!Y:Y,'Sales HC by Dept & T&E Segment'!$F:$F,$P21,'Sales HC by Dept & T&E Segment'!$G:$G,$G21) -> 259000 | W21: =SUMIFS('Sales HC by Dept & T&E Segment'!Z:Z,'Sales HC by Dept & T&E Segment'!$F:$F,$P21,'Sales HC by Dept & T&E Segment'!$G:$G,$G21) -> 259000 | X21: =SUMIFS('Sales HC by Dept & T&E Segment'!AA:AA,'Sales HC by Dept & T&E Segment'!$F:$F,$P21,'Sales HC by Dept & T&E Segment'!$G:$G,$G21) -> 259000 | Y21: =SUMIFS('Sales HC by Dept & T&E Segment'!AB:AB,'Sales HC by Dept & T&E Segment'!$F:$F,$P21,'Sales HC by Dept & T&E Segment'!$G:$G,$G21) -> 259000 | Z21: =SUMIFS('Sales HC by Dept & T&E Segment'!AC:AC,'Sales HC by Dept & T&E Segment'!$F:$F,$P21,'Sales HC by Dept & T&E Segment'!$G:$G,$G21) -> 259000 | AA21: =SUMIFS('Sales HC by Dept & T&E Segment'!AD:AD,'Sales HC by Dept & T&E Segment'!$F:$F,$P21,'Sales HC by Dept & T&E Segment'!$G:$G,$G21) -> 259000 | AB21: =SUMIFS('Sales HC by Dept & T&E Segment'!AE:AE,'Sales HC by Dept & T&E Segment'!$F:$F,$P21,'Sales HC by Dept & T&E Segment'!$G:$G,$G21) -> 259000 | AC21: =SUMIFS('Sales HC by Dept & T&E Segment'!AF:AF,'Sales HC by Dept & T&E Segment'!$F:$F,$P21,'Sales HC by Dept & T&E Segment'!$G:$G,$G21) -> 259000 | AD21: =SUMIFS('Sales HC by Dept & T&E Segment'!AG:AG,'Sales HC by Dept & T&E Segment'!$F:$F,$P21,'Sales HC by Dept & T&E Segment'!$G:$G,$G21) -> 259000 | AE21: =SUM(S21:AD21) -> 3009000 | AI21: =SUM(S21:U21) -> 678000 | AJ21: =SUM(V21:X21) -> 777000 | AK21: =SUM(Y21:AA21) -> 777000 | AL21: =SUM(AB21:AD21) -> 777000 | AM21: =SUM(AI21:AL21) -> 3009000 | AN21: =AM21-AE21 -> 0 | AP21: =SUM(AI21:AJ21) -> 1455000 | AQ21: =SUM(AK21:AL21) -> 1554000 | AR21: =AP21+AQ21-AM21 -> 0
B22: C110107102 | C22: 10107102 | D22: 西区-Nefecon | E22: T&E | F22: T&E | G22: Nefecon | H22: 2026 | I22: Budget | J22: Commercial | K22: Mainland | L22: CPO Operations | M22: Sales Team | N22: West | O22: West | P22: 西区 | S22: =SUMIFS('Sales HC by Dept & T&E Segment'!V:V,'Sales HC by Dept & T&E Segment'!$F:$F,$P22,'Sales HC by Dept & T&E Segment'!$G:$G,$G22) -> 197000 | T22: =SUMIFS('Sales HC by Dept & T&E Segment'!W:W,'Sales HC by Dept & T&E Segment'!$F:$F,$P22,'Sales HC by Dept & T&E Segment'!$G:$G,$G22) -> 197000 | U22: =SUMIFS('Sales HC by Dept & T&E Segment'!X:X,'Sales HC by Dept & T&E Segment'!$F:$F,$P22,'Sales HC by Dept & T&E Segment'!$G:$G,$G22) -> 197000 | V22: =SUMIFS('Sales HC by Dept & T&E Segment'!Y:Y,'Sales HC by Dept & T&E Segment'!$F:$F,$P22,'Sales HC by Dept & T&E Segment'!$G:$G,$G22) -> 237000 | W22: =SUMIFS('Sales HC by Dept & T&E Segment'!Z:Z,'Sales HC by Dept & T&E Segment'!$F:$F,$P22,'Sales HC by Dept & T&E Segment'!$G:$G,$G22) -> 237000 | X22: =SUMIFS('Sales HC by Dept & T&E Segment'!AA:AA,'Sales HC by Dept & T&E Segment'!$F:$F,$P22,'Sales HC by Dept & T&E Segment'!$G:$G,$G22) -> 237000 | Y22: =SUMIFS('Sales HC by Dept & T&E Segment'!AB:AB,'Sales HC by Dept & T&E Segment'!$F:$F,$P22,'Sales HC by Dept & T&E Segment'!$G:$G,$G22) -> 237000 | Z22: =SUMIFS('Sales HC by Dept & T&E Segment'!AC:AC,'Sales HC by Dept & T&E Segment'!$F:$F,$P22,'Sales HC by Dept & T&E Segment'!$G:$G,$G22) -> 237000 | AA22: =SUMIFS('Sales HC by Dept & T&E Segment'!AD:AD,'Sales HC by Dept & T&E Segment'!$F:$F,$P22,'Sales HC by Dept & T&E Segment'!$G:$G,$G22) -> 237000 | AB22: =SUMIFS('Sales HC by Dept & T&E Segment'!AE:AE,'Sales HC by Dept & T&E Segment'!$F:$F,$P22,'Sales HC by Dept & T&E Segment'!$G:$G,$G22) -> 237000 | AC22: =SUMIFS('Sales HC by Dept & T&E Segment'!AF:AF,'Sales HC by Dept & T&E Segment'!$F:$F,$P22,'Sales HC by Dept & T&E Segment'!$G:$G,$G22) -> 237000 | AD22: =SUMIFS('Sales HC by Dept & T&E Segment'!AG:AG,'Sales HC by Dept & T&E Segment'!$F:$F,$P22,'Sales HC by Dept & T&E Segment'!$G:$G,$G22) -> 237000 | AE22: =SUM(S22:AD22) -> 2724000 | AG22: =SUM(AE13:AE22) -> 25707000 | AH22: =AG22-'Sales HC by Dept & T&E Segment'!S99 -> 0 | AI22: =SUM(S22:U22) -> 591000 | AJ22: =SUM(V22:X22) -> 711000 | AK22: =SUM(Y22:AA22) -> 711000 | AL22: =SUM(AB22:AD22) -> 711000 | AM22: =SUM(AI22:AL22) -> 2724000 | AN22: =AM22-AE22 -> 0 | AP22: =SUM(AI22:AJ22) -> 1302000 | AQ22: =SUM(AK22:AL22) -> 1422000 | AR22: =AP22+AQ22-AM22 -> 0
B23: C110110100 | C23: 10110100 | D23: Velsipity Sales | E23: T&E | F23: T&E | G23: Velsipity | H23: 2026 | I23: Budget | J23: Commercial | K23: Mainland | L23: CPO Operations | M23: Sales Team | N23: Velsipity Sales | O23: Velsipity Sales | P23: Velsipity Sales | S23: 539000 | T23: 539000 | U23: 539000 | V23: 639000 | W23: 639000 | X23: 639000 | Y23: 839000 | Z23: 839000 | AA23: 839000 | AB23: 1239000 | AC23: 1239000 | AD23: 1239000 | AE23: =SUM(S23:AD23) -> 9768000 | AG23: =AE23 -> 9768000 | AH23: =AE23-'Sales HC by Dept & T&E Segment'!S5 -> 0 | AI23: =SUM(S23:U23) -> 1617000 | AJ23: =SUM(V23:X23) -> 1917000 | AK23: =SUM(Y23:AA23) -> 2517000 | AL23: =SUM(AB23:AD23) -> 3717000 | AM23: =SUM(AI23:AL23) -> 9768000 | AN23: =AM23-AE23 -> 0 | AP23: =SUM(AI23:AJ23) -> 3534000 | AQ23: =SUM(AK23:AL23) -> 6234000 | AR23: =AP23+AQ23-AM23 -> 0
B25: C110005300 | C25: 10005300 | D25: CPO General | E25: T&E | F25: T&E | G25: Nefecon | H25: 2026 | I25: Budget | J25: Commercial | K25: Mainland | L25: CPO Operations | M25: CPO General | N25: CPO General | O25: CPO General | P25: CPO General | Q25: T&E Buffer | S25: 12604.167 | T25: 12604.167 | U25: 12604.167 | V25: 12604.167 | W25: 12604.167 | X25: 12604.167 | Y25: 12604.167 | Z25: 12604.167 | AA25: 12604.167 | AB25: 12604.167 | AC25: 12604.167 | AD25: 12604.167 | AE25: =SUM(S25:AD25) -> 151250 | AI25: =SUM(S25:U25) -> 37812.5 | AJ25: =SUM(V25:X25) -> 37812.5 | AK25: =SUM(Y25:AA25) -> 37812.5 | AL25: =SUM(AB25:AD25) -> 37812.5 | AM25: =SUM(AI25:AL25) -> 151250 | AN25: =AM25-AE25 -> 0 | AP25: =SUM(AI25:AJ25) -> 75625 | AQ25: =SUM(AK25:AL25) -> 75625 | AR25: =AP25+AQ25-AM25 -> 0
B29: CC1 | C29: CC2 | D29: Dept Name | E29: FP&A L1 | F29: FP&A L2 | G29: Brand | H29: Year | I29: Data Type | J29: Mgt Report L1 | K29: Mgt Report L2 | L29: Mgt Report L3 | M29: Mgt Report L4 | N29: Mgt Report L5 | O29: Mgt Report L6 | P29: CN Name | Q29: Note1 | R29: Note2 | S29: Jan | T29: Feb | U29: Mar | V29: Apr | W29: May | X29: Jun | Y29: Jul | Z29: Aug | AA29: Sep | AB29: Oct | AC29: Nov | AD29: Dec | AE29: FY
B30: C110101101 | C30: 10101101 | D30: 北一区-Xerava | E30: A&P | F30: A&P | G30: Xerava | H30: 2026 | I30: Budget | J30: Commercial | K30: Mainland | L30: CPO Operations | M30: Sales Team | N30: North 1 | O30: North 1 | P30: 北一区 | Q30: 科室会 | R30: 科室会 | S30: =SUMIFS('Sales HC by Dept & T&E Segment'!AL:AL,'Sales HC by Dept & T&E Segment'!$F:$F,$P30,'Sales HC by Dept & T&E Segment'!$G:$G,$G30) -> 75000 | T30: =SUMIFS('Sales HC by Dept & T&E Segment'!AM:AM,'Sales HC by Dept & T&E Segment'!$F:$F,$P30,'Sales HC by Dept & T&E Segment'!$G:$G,$G30) -> 75000 | U30: =SUMIFS('Sales HC by Dept & T&E Segment'!AN:AN,'Sales HC by Dept & T&E Segment'!$F:$F,$P30,'Sales HC by Dept & T&E Segment'!$G:$G,$G30) -> 75000 | V30: =SUMIFS('Sales HC by Dept & T&E Segment'!AO:AO,'Sales HC by Dept & T&E Segment'!$F:$F,$P30,'Sales HC by Dept & T&E Segment'!$G:$G,$G30) -> 75000 | W30: =SUMIFS('Sales HC by Dept & T&E Segment'!AP:AP,'Sales HC by Dept & T&E Segment'!$F:$F,$P30,'Sales HC by Dept & T&E Segment'!$G:$G,$G30) -> 75000 | X30: =SUMIFS('Sales HC by Dept & T&E Segment'!AQ:AQ,'Sales HC by Dept & T&E Segment'!$F:$F,$P30,'Sales HC by Dept & T&E Segment'!$G:$G,$G30) -> 75000 | Y30: =SUMIFS('Sales HC by Dept & T&E Segment'!AR:AR,'Sales HC by Dept & T&E Segment'!$F:$F,$P30,'Sales HC by Dept & T&E Segment'!$G:$G,$G30) -> 75000 | Z30: =SUMIFS('Sales HC by Dept & T&E Segment'!AS:AS,'Sales HC by Dept & T&E Segment'!$F:$F,$P30,'Sales HC by Dept & T&E Segment'!$G:$G,$G30) -> 75000 | AA30: =SUMIFS('Sales HC by Dept & T&E Segment'!AT:AT,'Sales HC by Dept & T&E Segment'!$F:$F,$P30,'Sales HC by Dept & T&E Segment'!$G:$G,$G30) -> 75000 | AB30: =SUMIFS('Sales HC by Dept & T&E Segment'!AU:AU,'Sales HC by Dept & T&E Segment'!$F:$F,$P30,'Sales HC by Dept & T&E Segment'!$G:$G,$G30) -> 75000 | AC30: =SUMIFS('Sales HC by Dept & T&E Segment'!AV:AV,'Sales HC by Dept & T&E Segment'!$F:$F,$P30,'Sales HC by Dept & T&E Segment'!$G:$G,$G30) -> 75000 | AD30: =SUMIFS('Sales HC by Dept & T&E Segment'!AW:AW,'Sales HC by Dept & T&E Segment'!$F:$F,$P30,'Sales HC by Dept & T&E Segment'!$G:$G,$G30) -> 75000 | AE30: =SUM(S30:AD30) -> 900000 | AI30: =SUM(S30:U30) -> 225000 | AJ30: =SUM(V30:X30) -> 225000 | AK30: =SUM(Y30:AA30) -> 225000 | AL30: =SUM(AB30:AD30) -> 225000 | AM30: =SUM(AI30:AL30) -> 900000 | AN30: =AM30-AE30 -> 0 | AP30: =SUM(AI30:AJ30) -> 450000 | AQ30: =SUM(AK30:AL30) -> 450000 | AR30: =AP30+AQ30-AM30 -> 0
B31: C110101201 | C31: 10101201 | D31: 北二区-Xerava | E31: A&P | F31: A&P | G31: Xerava | H31: 2026 | I31: Budget | J31: Commercial | K31: Mainland | L31: CPO Operations | M31: Sales Team | N31: North 2 | O31: North 2 | P31: 北二区 | Q31: 科室会 | R31: 科室会 | S31: =SUMIFS('Sales HC by Dept & T&E Segment'!AL:AL,'Sales HC by Dept & T&E Segment'!$F:$F,$P31,'Sales HC by Dept & T&E Segment'!$G:$G,$G31) -> 30000 | T31: =SUMIFS('Sales HC by Dept & T&E Segment'!AM:AM,'Sales HC by Dept & T&E Segment'!$F:$F,$P31,'Sales HC by Dept & T&E Segment'!$G:$G,$G31) -> 30000 | U31: =SUMIFS('Sales HC by Dept & T&E Segment'!AN:AN,'Sales HC by Dept & T&E Segment'!$F:$F,$P31,'Sales HC by Dept & T&E Segment'!$G:$G,$G31) -> 30000 | V31: =SUMIFS('Sales HC by Dept & T&E Segment'!AO:AO,'Sales HC by Dept & T&E Segment'!$F:$F,$P31,'Sales HC by Dept & T&E Segment'!$G:$G,$G31) -> 30000 | W31: =SUMIFS('Sales HC by Dept & T&E Segment'!AP:AP,'Sales HC by Dept & T&E Segment'!$F:$F,$P31,'Sales HC by Dept & T&E Segment'!$G:$G,$G31) -> 30000 | X31: =SUMIFS('Sales HC by Dept & T&E Segment'!AQ:AQ,'Sales HC by Dept & T&E Segment'!$F:$F,$P31,'Sales HC by Dept & T&E Segment'!$G:$G,$G31) -> 30000 | Y31: =SUMIFS('Sales HC by Dept & T&E Segment'!AR:AR,'Sales HC by Dept & T&E Segment'!$F:$F,$P31,'Sales HC by Dept & T&E Segment'!$G:$G,$G31) -> 30000 | Z31: =SUMIFS('Sales HC by Dept & T&E Segment'!AS:AS,'Sales HC by Dept & T&E Segment'!$F:$F,$P31,'Sales HC by Dept & T&E Segment'!$G:$G,$G31) -> 30000 | AA31: =SUMIFS('Sales HC by Dept & T&E Segment'!AT:AT,'Sales HC by Dept & T&E Segment'!$F:$F,$P31,'Sales HC by Dept & T&E Segment'!$G:$G,$G31) -> 30000 | AB31: =SUMIFS('Sales HC by Dept & T&E Segment'!AU:AU,'Sales HC by Dept & T&E Segment'!$F:$F,$P31,'Sales HC by Dept & T&E Segment'!$G:$G,$G31) -> 30000 | AC31: =SUMIFS('Sales HC by Dept & T&E Segment'!AV:AV,'Sales HC by Dept & T&E Segment'!$F:$F,$P31,'Sales HC by Dept & T&E Segment'!$G:$G,$G31) -> 30000 | AD31: =SUMIFS('Sales HC by Dept & T&E Segment'!AW:AW,'Sales HC by Dept & T&E Segment'!$F:$F,$P31,'Sales HC by Dept & T&E Segment'!$G:$G,$G31) -> 30000 | AE31: =SUM(S31:AD31) -> 360000 | AI31: =SUM(S31:U31) -> 90000 | AJ31: =SUM(V31:X31) -> 90000 | AK31: =SUM(Y31:AA31) -> 90000 | AL31: =SUM(AB31:AD31) -> 90000 | AM31: =SUM(AI31:AL31) -> 360000 | AN31: =AM31-AE31 -> 0 | AP31: =SUM(AI31:AJ31) -> 180000 | AQ31: =SUM(AK31:AL31) -> 180000 | AR31: =AP31+AQ31-AM31 -> 0
B32: C110101301 | C32: 10101301 | D32: 北三区-Xerava | E32: A&P | F32: A&P | G32: Xerava | H32: 2026 | I32: Budget | J32: Commercial | K32: Mainland | L32: CPO Operations | M32: Sales Team | N32: North 3 | O32: North 3 | P32: 北三区 | Q32: 科室会 | R32: 科室会 | S32: =SUMIFS('Sales HC by Dept & T&E Segment'!AL:AL,'Sales HC by Dept & T&E Segment'!$F:$F,$P32,'Sales HC by Dept & T&E Segment'!$G:$G,$G32) -> 48000 | T32: =SUMIFS('Sales HC by Dept & T&E Segment'!AM:AM,'Sales HC by Dept & T&E Segment'!$F:$F,$P32,'Sales HC by Dept & T&E Segment'!$G:$G,$G32) -> 48000 | U32: =SUMIFS('Sales HC by Dept & T&E Segment'!AN:AN,'Sales HC by Dept & T&E Segment'!$F:$F,$P32,'Sales HC by Dept & T&E Segment'!$G:$G,$G32) -> 48000 | V32: =SUMIFS('Sales HC by Dept & T&E Segment'!AO:AO,'Sales HC by Dept & T&E Segment'!$F:$F,$P32,'Sales HC by Dept & T&E Segment'!$G:$G,$G32) -> 48000 | W32: =SUMIFS('Sales HC by Dept & T&E Segment'!AP:AP,'Sales HC by Dept & T&E Segment'!$F:$F,$P32,'Sales HC by Dept & T&E Segment'!$G:$G,$G32) -> 48000 | X32: =SUMIFS('Sales HC by Dept & T&E Segment'!AQ:AQ,'Sales HC by Dept & T&E Segment'!$F:$F,$P32,'Sales HC by Dept & T&E Segment'!$G:$G,$G32) -> 48000 | Y32: =SUMIFS('Sales HC by Dept & T&E Segment'!AR:AR,'Sales HC by Dept & T&E Segment'!$F:$F,$P32,'Sales HC by Dept & T&E Segment'!$G:$G,$G32) -> 48000 | Z32: =SUMIFS('Sales HC by Dept & T&E Segment'!AS:AS,'Sales HC by Dept & T&E Segment'!$F:$F,$P32,'Sales HC by Dept & T&E Segment'!$G:$G,$G32) -> 48000 | AA32: =SUMIFS('Sales HC by Dept & T&E Segment'!AT:AT,'Sales HC by Dept & T&E Segment'!$F:$F,$P32,'Sales HC by Dept & T&E Segment'!$G:$G,$G32) -> 48000 | AB32: =SUMIFS('Sales HC by Dept & T&E Segment'!AU:AU,'Sales HC by Dept & T&E Segment'!$F:$F,$P32,'Sales HC by Dept & T&E Segment'!$G:$G,$G32) -> 48000 | AC32: =SUMIFS('Sales HC by Dept & T&E Segment'!AV:AV,'Sales HC by Dept & T&E Segment'!$F:$F,$P32,'Sales HC by Dept & T&E Segment'!$G:$G,$G32) -> 48000 | AD32: =SUMIFS('Sales HC by Dept & T&E Segment'!AW:AW,'Sales HC by Dept & T&E Segment'!$F:$F,$P32,'Sales HC by Dept & T&E Segment'!$G:$G,$G32) -> 48000 | AE32: =SUM(S32:AD32) -> 576000 | AI32: =SUM(S32:U32) -> 144000 | AJ32: =SUM(V32:X32) -> 144000 | AK32: =SUM(Y32:AA32) -> 144000 | AL32: =SUM(AB32:AD32) -> 144000 | AM32: =SUM(AI32:AL32) -> 576000 | AN32: =AM32-AE32 -> 0 | AP32: =SUM(AI32:AJ32) -> 288000 | AQ32: =SUM(AK32:AL32) -> 288000 | AR32: =AP32+AQ32-AM32 -> 0
B33: C110102101 | C33: 10102101 | D33: 东一区-Xerava | E33: A&P | F33: A&P | G33: Xerava | H33: 2026 | I33: Budget | J33: Commercial | K33: Mainland | L33: CPO Operations | M33: Sales Team | N33: East 1 | O33: East 1 | P33: 东一区 | Q33: 科室会 | R33: 科室会 | S33: =SUMIFS('Sales HC by Dept & T&E Segment'!AL:AL,'Sales HC by Dept & T&E Segment'!$F:$F,$P33,'Sales HC by Dept & T&E Segment'!$G:$G,$G33) -> 54000 | T33: =SUMIFS('Sales HC by Dept & T&E Segment'!AM:AM,'Sales HC by Dept & T&E Segment'!$F:$F,$P33,'Sales HC by Dept & T&E Segment'!$G:$G,$G33) -> 54000 | U33: =SUMIFS('Sales HC by Dept & T&E Segment'!AN:AN,'Sales HC by Dept & T&E Segment'!$F:$F,$P33,'Sales HC by Dept & T&E Segment'!$G:$G,$G33) -> 54000 | V33: =SUMIFS('Sales HC by Dept & T&E Segment'!AO:AO,'Sales HC by Dept & T&E Segment'!$F:$F,$P33,'Sales HC by Dept & T&E Segment'!$G:$G,$G33) -> 54000 | W33: =SUMIFS('Sales HC by Dept & T&E Segment'!AP:AP,'Sales HC by Dept & T&E Segment'!$F:$F,$P33,'Sales HC by Dept & T&E Segment'!$G:$G,$G33) -> 54000 | X33: =SUMIFS('Sales HC by Dept & T&E Segment'!AQ:AQ,'Sales HC by Dept & T&E Segment'!$F:$F,$P33,'Sales HC by Dept & T&E Segment'!$G:$G,$G33) -> 54000 | Y33: =SUMIFS('Sales HC by Dept & T&E Segment'!AR:AR,'Sales HC by Dept & T&E Segment'!$F:$F,$P33,'Sales HC by Dept & T&E Segment'!$G:$G,$G33) -> 54000 | Z33: =SUMIFS('Sales HC by Dept & T&E Segment'!AS:AS,'Sales HC by Dept & T&E Segment'!$F:$F,$P33,'Sales HC by Dept & T&E Segment'!$G:$G,$G33) -> 54000 | AA33: =SUMIFS('Sales HC by Dept & T&E Segment'!AT:AT,'Sales HC by Dept & T&E Segment'!$F:$F,$P33,'Sales HC by Dept & T&E Segment'!$G:$G,$G33) -> 54000 | AB33: =SUMIFS('Sales HC by Dept & T&E Segment'!AU:AU,'Sales HC by Dept & T&E Segment'!$F:$F,$P33,'Sales HC by Dept & T&E Segment'!$G:$G,$G33) -> 54000 | AC33: =SUMIFS('Sales HC by Dept & T&E Segment'!AV:AV,'Sales HC by Dept & T&E Segment'!$F:$F,$P33,'Sales HC by Dept & T&E Segment'!$G:$G,$G33) -> 54000 | AD33: =SUMIFS('Sales HC by Dept & T&E Segment'!AW:AW,'Sales HC by Dept & T&E Segment'!$F:$F,$P33,'Sales HC by Dept & T&E Segment'!$G:$G,$G33) -> 54000 | AE33: =SUM(S33:AD33) -> 648000 | AI33: =SUM(S33:U33) -> 162000 | AJ33: =SUM(V33:X33) -> 162000 | AK33: =SUM(Y33:AA33) -> 162000 | AL33: =SUM(AB33:AD33) -> 162000 | AM33: =SUM(AI33:AL33) -> 648000 | AN33: =AM33-AE33 -> 0 | AP33: =SUM(AI33:AJ33) -> 324000 | AQ33: =SUM(AK33:AL33) -> 324000 | AR33: =AP33+AQ33-AM33 -> 0
